Workbook

Sheet Dashboard
A1: Growize App — Test Execution Dashboard
A2: Owner: ARL Tech
A3: Cycle: Pre-launch 2026-05-05 + ongoing daily UAT (hybrid)
A4: Rule: CRM observed only. Demo records suffix '-demo'. Fixes go in Supabase / app / sync / RLS — never CRM.
A6: Execution Summary (manual weekly + pre-release pass)
A7: Metric | B7: Value | C7: Source
A8: Total test cases | B8: =COUNTA('Test Cases'!A4:A1000) | C8: Count of TC IDs
A9: Executed | B9: =COUNTIF('Test Cases'!J4:J1000,"Pass")+COUNTIF('Test Cases'!J4:J1000,"Fail")+COUNTIF('Test Cases'!J4:J1000,"Blocked")+COUNTIF('Test Cases'!J4:J1000,"N/A") | C9: Status not Not Run
A10: Passed | B10: =COUNTIF('Test Cases'!J4:J1000,"Pass") | C10: Status = Pass
A11: Failed | B11: =COUNTIF('Test Cases'!J4:J1000,"Fail") | C11: Status = Fail
A12: Blocked | B12: =COUNTIF('Test Cases'!J4:J1000,"Blocked") | C12: Status = Blocked
A13: N/A | B13: =COUNTIF('Test Cases'!J4:J1000,"N/A") | C13: Status = N/A
A14: Not Run | B14: =COUNTIF('Test Cases'!J4:J1000,"Not Run") | C14: Remaining
A15: Pass rate | B15: =IFERROR(B10/(B10+B11),0) | C15: Pass / (Pass + Fail)
A16: Open defects | B16: =COUNTIFS(Defects!I4:I1000,"Open")+COUNTIFS(Defects!I4:I1000,"Triaged")+COUNTIFS(Defects!I4:I1000,"In Progress")+COUNTIFS(Defects!I4:I1000,"Ready to Re-test") | C16: Defects sheet
A17: Critical (S1) open | B17: =COUNTIFS(Defects!G4:G1000,"S1",Defects!I4:I1000,"<>Closed-Pass",Defects!I4:I1000,"<>Closed-Wont Fix",Defects!I4:I1000,"<>Closed-Duplicate") | C17: Severity S1, not closed
A18: High (S2) open | B18: =COUNTIFS(Defects!G4:G1000,"S2",Defects!I4:I1000,"<>Closed-Pass",Defects!I4:I1000,"<>Closed-Wont Fix",Defects!I4:I1000,"<>Closed-Duplicate") | C18: Severity S2, not closed
A19: Defects closed | B19: =COUNTIF(Defects!I4:I1000,"Closed-Pass") | C19: Resolved
A21: Daily UAT (automated)
A22: Metric | B22: Value | C22: Source
A23: Last run date | B23: ='Daily UAT'!E1 | C23: Most recent run column header
A24: Last run pass rate | B24: =IFERROR('Daily UAT'!E22,0) | C24: Pass count / total
A25: Cases in daily set | B25: =COUNTA('Daily UAT'!A4:A21) | C25: D-## rows
A26: Days run | B26: =COUNTA('Daily UAT'!E2:ZZ2) | C26: Date headers
A29: Coverage by area
A30: Area | B30: Total cases | C30: Pass | D30: Fail | E30: Blocked | F30: Not Run | G30: Pass %
A31: LLP | B31: =COUNTIF('Test Cases'!A4:A1000,"*-LLP-*") | C31: =COUNTIFS('Test Cases'!A4:A1000,"*-LLP-*",'Test Cases'!J4:J1000,"Pass") | D31: =COUNTIFS('Test Cases'!A4:A1000,"*-LLP-*",'Test Cases'!J4:J1000,"Fail") | E31: =COUNTIFS('Test Cases'!A4:A1000,"*-LLP-*",'Test Cases'!J4:J1000,"Blocked") | F31: =B31-C31-D31-E31-COUNTIFS('Test Cases'!A4:A1000,"*-LLP-*",'Test Cases'!J4:J1000,"N/A") | G31: =IFERROR(C31/(C31+D31),0)
A32: PRJ | B32: =COUNTIF('Test Cases'!A4:A1000,"*-PRJ-*") | C32: =COUNTIFS('Test Cases'!A4:A1000,"*-PRJ-*",'Test Cases'!J4:J1000,"Pass") | D32: =COUNTIFS('Test Cases'!A4:A1000,"*-PRJ-*",'Test Cases'!J4:J1000,"Fail") | E32: =COUNTIFS('Test Cases'!A4:A1000,"*-PRJ-*",'Test Cases'!J4:J1000,"Blocked") | F32: =B32-C32-D32-E32-COUNTIFS('Test Cases'!A4:A1000,"*-PRJ-*",'Test Cases'!J4:J1000,"N/A") | G32: =IFERROR(C32/(C32+D32),0)
A33: INV | B33: =COUNTIF('Test Cases'!A4:A1000,"*-INV-*") | C33: =COUNTIFS('Test Cases'!A4:A1000,"*-INV-*",'Test Cases'!J4:J1000,"Pass") | D33: =COUNTIFS('Test Cases'!A4:A1000,"*-INV-*",'Test Cases'!J4:J1000,"Fail") | E33: =COUNTIFS('Test Cases'!A4:A1000,"*-INV-*",'Test Cases'!J4:J1000,"Blocked") | F33: =B33-C33-D33-E33-COUNTIFS('Test Cases'!A4:A1000,"*-INV-*",'Test Cases'!J4:J1000,"N/A") | G33: =IFERROR(C33/(C33+D33),0)
A34: ALC | B34: =COUNTIF('Test Cases'!A4:A1000,"*-ALC-*") | C34: =COUNTIFS('Test Cases'!A4:A1000,"*-ALC-*",'Test Cases'!J4:J1000,"Pass") | D34: =COUNTIFS('Test Cases'!A4:A1000,"*-ALC-*",'Test Cases'!J4:J1000,"Fail") | E34: =COUNTIFS('Test Cases'!A4:A1000,"*-ALC-*",'Test Cases'!J4:J1000,"Blocked") | F34: =B34-C34-D34-E34-COUNTIFS('Test Cases'!A4:A1000,"*-ALC-*",'Test Cases'!J4:J1000,"N/A") | G34: =IFERROR(C34/(C34+D34),0)
A35: AUTH | B35: =COUNTIF('Test Cases'!A4:A1000,"*-AUTH-*") | C35: =COUNTIFS('Test Cases'!A4:A1000,"*-AUTH-*",'Test Cases'!J4:J1000,"Pass") | D35: =COUNTIFS('Test Cases'!A4:A1000,"*-AUTH-*",'Test Cases'!J4:J1000,"Fail") | E35: =COUNTIFS('Test Cases'!A4:A1000,"*-AUTH-*",'Test Cases'!J4:J1000,"Blocked") | F35: =B35-C35-D35-E35-COUNTIFS('Test Cases'!A4:A1000,"*-AUTH-*",'Test Cases'!J4:J1000,"N/A") | G35: =IFERROR(C35/(C35+D35),0)
A36: APP | B36: =COUNTIF('Test Cases'!A4:A1000,"*-APP-*") | C36: =COUNTIFS('Test Cases'!A4:A1000,"*-APP-*",'Test Cases'!J4:J1000,"Pass") | D36: =COUNTIFS('Test Cases'!A4:A1000,"*-APP-*",'Test Cases'!J4:J1000,"Fail") | E36: =COUNTIFS('Test Cases'!A4:A1000,"*-APP-*",'Test Cases'!J4:J1000,"Blocked") | F36: =B36-C36-D36-E36-COUNTIFS('Test Cases'!A4:A1000,"*-APP-*",'Test Cases'!J4:J1000,"N/A") | G36: =IFERROR(C36/(C36+D36),0)
A37: DOC | B37: =COUNTIF('Test Cases'!A4:A1000,"*-DOC-*") | C37: =COUNTIFS('Test Cases'!A4:A1000,"*-DOC-*",'Test Cases'!J4:J1000,"Pass") | D37: =COUNTIFS('Test Cases'!A4:A1000,"*-DOC-*",'Test Cases'!J4:J1000,"Fail") | E37: =COUNTIFS('Test Cases'!A4:A1000,"*-DOC-*",'Test Cases'!J4:J1000,"Blocked") | F37: =B37-C37-D37-E37-COUNTIFS('Test Cases'!A4:A1000,"*-DOC-*",'Test Cases'!J4:J1000,"N/A") | G37: =IFERROR(C37/(C37+D37),0)
A38: EXIT | B38: =COUNTIF('Test Cases'!A4:A1000,"*-EXIT-*") | C38: =COUNTIFS('Test Cases'!A4:A1000,"*-EXIT-*",'Test Cases'!J4:J1000,"Pass") | D38: =COUNTIFS('Test Cases'!A4:A1000,"*-EXIT-*",'Test Cases'!J4:J1000,"Fail") | E38: =COUNTIFS('Test Cases'!A4:A1000,"*-EXIT-*",'Test Cases'!J4:J1000,"Blocked") | F38: =B38-C38-D38-E38-COUNTIFS('Test Cases'!A4:A1000,"*-EXIT-*",'Test Cases'!J4:J1000,"N/A") | G38: =IFERROR(C38/(C38+D38),0)
A39: SYNC | B39: =COUNTIF('Test Cases'!A4:A1000,"*-SYNC-*") | C39: =COUNTIFS('Test Cases'!A4:A1000,"*-SYNC-*",'Test Cases'!J4:J1000,"Pass") | D39: =COUNTIFS('Test Cases'!A4:A1000,"*-SYNC-*",'Test Cases'!J4:J1000,"Fail") | E39: =COUNTIFS('Test Cases'!A4:A1000,"*-SYNC-*",'Test Cases'!J4:J1000,"Blocked") | F39: =B39-C39-D39-E39-COUNTIFS('Test Cases'!A4:A1000,"*-SYNC-*",'Test Cases'!J4:J1000,"N/A") | G39: =IFERROR(C39/(C39+D39),0)
A40: RLS | B40: =COUNTIF('Test Cases'!A4:A1000,"*-RLS-*") | C40: =COUNTIFS('Test Cases'!A4:A1000,"*-RLS-*",'Test Cases'!J4:J1000,"Pass") | D40: =COUNTIFS('Test Cases'!A4:A1000,"*-RLS-*",'Test Cases'!J4:J1000,"Fail") | E40: =COUNTIFS('Test Cases'!A4:A1000,"*-RLS-*",'Test Cases'!J4:J1000,"Blocked") | F40: =B40-C40-D40-E40-COUNTIFS('Test Cases'!A4:A1000,"*-RLS-*",'Test Cases'!J4:J1000,"N/A") | G40: =IFERROR(C40/(C40+D40),0)
A41: OBS | B41: =COUNTIF('Test Cases'!A4:A1000,"*-OBS-*") | C41: =COUNTIFS('Test Cases'!A4:A1000,"*-OBS-*",'Test Cases'!J4:J1000,"Pass") | D41: =COUNTIFS('Test Cases'!A4:A1000,"*-OBS-*",'Test Cases'!J4:J1000,"Fail") | E41: =COUNTIFS('Test Cases'!A4:A1000,"*-OBS-*",'Test Cases'!J4:J1000,"Blocked") | F41: =B41-C41-D41-E41-COUNTIFS('Test Cases'!A4:A1000,"*-OBS-*",'Test Cases'!J4:J1000,"N/A") | G41: =IFERROR(C41/(C41+D41),0)
A42: NEG | B42: =COUNTIF('Test Cases'!A4:A1000,"*-NEG-*") | C42: =COUNTIFS('Test Cases'!A4:A1000,"*-NEG-*",'Test Cases'!J4:J1000,"Pass") | D42: =COUNTIFS('Test Cases'!A4:A1000,"*-NEG-*",'Test Cases'!J4:J1000,"Fail") | E42: =COUNTIFS('Test Cases'!A4:A1000,"*-NEG-*",'Test Cases'!J4:J1000,"Blocked") | F42: =B42-C42-D42-E42-COUNTIFS('Test Cases'!A4:A1000,"*-NEG-*",'Test Cases'!J4:J1000,"N/A") | G42: =IFERROR(C42/(C42+D42),0)
A44: Notes
A45: 1. CRM is observed only. Demo records have name suffix '-demo'. Never write to CRM during testing.
...

Sheet Fixture Spec
A1: Fixture Spec — '-demo' records required in CRM
A2: Create these in Zoho CRM with name suffix '-demo'. Fill CRM ID and Supabase verification status.
A4: Fixture key | B4: Type | C4: Required attributes | D4: CRM ID (fill in) | E4: Verified in CRM | F4: Verified in Supabase | G4: Notes
A5: F-LLP-A | B5: LLP | C5: Active LLP with 2 child projects (1 Active, 1 Not Started) | D5: 1169101000001433001 | E5: Yes | F5: No
A6: F-LLP-B | B6: LLP | C6: Active LLP with 1 active project, single allocated investor | D6: 1169101000001433017 | E6: Yes | F6: No
A7: F-LLP-C | B7: LLP | C7: Active LLP with zero projects | D7: 1169101000001439003 | E7: Yes | F7: No
A8: F-LLP-A2 | B8: LLP | C8: LLP/project, status Open for Reservation (Not Started). 500 units, ₹20000/unit. Used by SC-ALC-002. | D8: 1169101000001433016 | E8: Yes | F8: No
A9: F-LLP-EXIT | B9: LLP | C9: LLP/project, status Fully Subscribed/Closed. 600 units, ₹15000/unit. Used by SC-EXIT-001. | D9: 1169101000001433018 | E9: Yes | F9: No
A10: (unused) | C10: Was F-PRJ-B1; merged into F-LLP-B per rewrite (LLP = project). | E10: N/A | F10: N/A
A11: (unused) | C11: Was F-PRJ-EXIT; merged into F-LLP-EXIT per rewrite (LLP = project). | E11: N/A | F11: N/A
A12: F-INV-01 | B12: Investor | C12: Onboarded. One Paid + Active allocation. | D12: 1169101000001467016 | E12: Yes | F12: No
A13: F-INV-02 | B13: Investor | C13: Onboarded. One Paid + Not Started allocation. | D13: 1169101000001467017 | E13: Yes | F13: No
A14: F-INV-03 | B14: Investor | C14: Onboarded. One Pending allocation (paid 0). | D14: 1169101000001467018 | E14: Yes | F14: No
A15: F-INV-04 | B15: Investor | C15: Onboarded. One Partial allocation (paid 50%). | D15: 1169101000001467019 | E15: Yes | F15: No
A16: F-INV-05 | B16: Investor | C16: Onboarded. Multi-project across two LLPs. | D16: 1169101000001467020 | E16: Yes | F16: No
A17: F-INV-06 | B17: Investor | C17: Onboarded. Zero allocations (empty-state). | D17: 1169101000001467021 | E17: Yes | F17: No
A18: F-INV-07 | B18: Investor | C18: Two CRM contacts share same email (negative). | D18: 1169101000001467022 | E18: Yes | F18: No
A19: F-ALC-01 | B19: Allocation | C19: F-INV-01 -> F-PRJ-A1. Paid + Active. | D19: 1169101000001466002 | E19: Yes | F19: No
A20: F-ALC-02 | B20: Allocation | C20: F-INV-02 -> F-PRJ-A2. Paid + Not Started. | D20: 1169101000001430008 | E20: Yes | F20: No
A21: F-ALC-03 | B21: Allocation | C21: F-INV-03 -> F-PRJ-A1. Pending (paid=0). | D21: 1169101000001430009 | E21: Yes | F21: No
A22: F-ALC-04 | B22: Allocation | C22: F-INV-04 -> F-PRJ-A1. Partial (paid 50%). | D22: 1169101000001430010 | E22: Yes | F22: No
A23: F-ALC-05 | B23: Allocation | C23: F-INV-05 -> F-PRJ-A1. Paid + Active. | D23: 1169101000001430011 | E23: Yes | F23: No
... A25: F-ALC-EXIT | B25: Allocation | C25: F-INV-01 -> F-PRJ-EXIT. Closed with payout. | D25: 1169101000001430013 | E25: Yes | F25: No
A26: F-DOC-01 | B26: Document | C26: One PDF scoped to F-INV-01 only. | E26: No | F26: No

Sheet Scenarios
A1: Test Scenarios
A3: Scenario ID | B3: Area | C3: Title | D3: Goal | E3: Required fixtures | F3: Linked test cases | G3: Status
A4: SC-LLP-001 | B4: LLP | C4: LLP visibility | D4: Demo LLP in CRM is reflected in Supabase and visible in app. | E4: F-LLP-A | F4: TC-LLP-001-01..04 | G4: Not Started
A5: SC-LLP-002 | B5: LLP | C5: Empty LLP | D5: LLP with zero projects renders empty state without crash. | E5: F-LLP-C | F5: TC-LLP-002-01..02 | G5: Not Started
A6: SC-PRJ-001 | B6: PRJ | C6: Project under LLP | D6: Project linked to LLP appears in app for allocated investors only. | E6: F-LLP-A, F-PRJ-A1 | F6: TC-PRJ-001-01..03 | G6: Not Started
A7: SC-PRJ-002 | B7: PRJ | C7: Project state transitions | D7: Project state changes propagate correctly (observed when ops transitions). | E7: F-PRJ-A2, F-PRJ-EXIT | F7: TC-PRJ-002-01..03 | G7: Not Started
A8: SC-INV-001 | B8: INV | C8: Investor lifecycle and login | D8: Onboarded investor logs in and sees own portfolio only. | E8: F-INV-01, F-INV-02 | F8: TC-INV-001-01..05 | G8: Not Started
A9: SC-ALC-001 | B9: ALC | C9: Paid + Active | D9: Paid investor sees units in active earning project. | E9: F-INV-01, F-PRJ-A1, F-ALC-01 | F9: TC-ALC-001-01..05 | G9: Not Started
A10: SC-ALC-002 | B10: ALC | C10: Paid + Not Started | D10: Paid investor with not-started project sees Reserved/Not Started state. | E10: F-INV-02, F-PRJ-A2, F-ALC-02 | F10: TC-ALC-002-01..03 | G10: Not Started
A11: SC-ALC-003 | B11: ALC | C11: Payment Pending | D11: Investor with units allocated but no payment received sees Pending. | E11: F-INV-03, F-PRJ-A1, F-ALC-03 | F11: TC-ALC-003-01..03 | G11: Not Started
A12: SC-ALC-004 | B12: ALC | C12: Partial Payment | D12: Partial-payment investor sees proportional state and outstanding balance. | E12: F-INV-04, F-PRJ-A1, F-ALC-04 | F12: TC-ALC-004-01..03 | G12: Not Started
A13: SC-ALC-005 | B13: ALC | C13: Multi-project investor | D13: Investor allocated across multiple projects/LLPs sees aggregated portfolio. | E13: F-INV-05, F-PRJ-A1, F-PRJ-B1, F-ALC-05, F-ALC-06 | F13: TC-ALC-005-01..04 | G13: Not Started
A14: SC-AUTH-001 | B14: AUTH | C14: Authentication and isolation | D14: Authenticated user maps to one investor and sees only their data. | E14: F-INV-01, F-INV-02 | F14: TC-AUTH-001-01..05 | G14: Not Started
... A20: SC-OBS-001 | B20: OBS | C20: Observability | D20: Sentry, edge function logs, and Slack alerts wired correctly. | E20: Daily-UAT service account | F20: TC-OBS-001-01..03 | G20: Not Started

Sheet Test Cases
A1: Test Cases — Step-by-step (weekly + pre-release human pass)
A3: TC ID | B3: Scenario ID | C3: Step | D3: Pre-condition | E3: Action / Verification | F3: Expected result | G3: Layer | H3: Priority | I3: Fixture(s) | J3: Status | K3: Tester | L3: Date | M3: Defect IDs | N3: Notes / Actual
A4: TC-LLP-001-01 | B4: SC-LLP-001 | C4: 1 | D4: Fixture spec filled | E4: Confirm F-LLP-A '-demo' LLP exists in CRM (read-only observation). | F4: Record visible with expected name/status. | G4: Sync | H4: P0 | I4: F-LLP-A | J4: Skipped | K4: Claude (Opus 4.7) | L4: 2026-05-07 | N4: Skipped: anon key only; RLS denies. Need investor session token (daily-uat service account, not provided).
A5: TC-LLP-001-02 | B5: SC-LLP-001 | C5: 2 | D5: Sync ran | E5: Query Supabase llps table for F-LLP-A row. | F5: Row exists; matches name/status; FK to CRM ID. | G5: Supabase | H5: P0 | I5: F-LLP-A | J5: Pass | K5: Claude (Opus 4.7) — authenticated | L5: 2026-05-07 | N5: Authenticated session: llps table accessible. Visible LLPs: Pineapple Enterprises(Open for Reservation), Samsung LLP(Open for Reservation), Xiaomi LLP(Active). Schema: llp_status (not status). FK zoho_llp_id present.
A6: TC-LLP-001-03 | B6: SC-LLP-001 | C6: 3 | D6: Investor onboarded | E6: Login app as F-INV-01. | F6: Project list under F-LLP-A renders. No errors. | G6: App | H6: P0 | I6: F-INV-01, F-LLP-A | J6: Skipped | K6: Claude (Opus 4.7) | L6: 2026-05-07 | N6: Skipped: anon key only; RLS denies. Need investor session token (daily-uat service account, not provided).
A7: TC-LLP-001-04 | B7: SC-LLP-001 | C7: 4 | D7: CRM record changes (legitimately) | E7: Wait for sync after a CRM update; refresh app. | F7: Updated value visible in Supabase + app. | G7: Sync | H7: P1 | I7: F-LLP-A | J7: Skipped | K7: Claude (Opus 4.7) | L7: 2026-05-07 | N7: Skipped: anon key only; RLS denies. Need investor session token (daily-uat service account, not provided).
A8: TC-LLP-002-01 | B8: SC-LLP-002 | C8: 1 | D8: Sync ran | E8: Query Supabase: count(projects where llp_id = F-LLP-C). | F8: Count = 0. | G8: Supabase | H8: P1 | I8: F-LLP-C | J8: Skipped | K8: Claude (Opus 4.7) — authenticated | L8: 2026-05-07 | N8: Empty LLP fixture (F-LLP-C) not visible to test investor. Need investor mapped to empty LLP, or service-role read.
A9: TC-LLP-002-02 | B9: SC-LLP-002 | C9: 2 | D9: Test investor with explore access | E9: Open explore screen showing F-LLP-C. | F9: Empty state rendered; no crash, no infinite loader. | G9: App | H9: P1 | I9: F-LLP-C | J9: Skipped | K9: Claude (Opus 4.7) — authenticated | L9: 2026-05-07 | N9: Same as TC-LLP-002-01.
A10: TC-PRJ-001-01 | B10: SC-PRJ-001 | C10: 1 | D10: Sync ran | E10: Verify F-PRJ-A1 in Supabase projects. | F10: Row exists; FK to F-LLP-A; status Active; total_units, unit_value populated. | G10: Supabase | H10: P0 | I10: F-PRJ-A1 | J10: Pass | K10: Claude (Opus 4.7) — UAT-by-data | L10: 2026-05-11 | N10: 3 projects FK-resolve to 3 LLPs; tier=25L; total_units populated.
A11: TC-PRJ-001-02 | B11: SC-PRJ-001 | C11: 2 | D11: Investor onboarded | E11: Login as F-INV-01; view portfolio. | F11: F-PRJ-A1 visible with units (per F-ALC-01). | G11: App | H11: P0 | I11: F-INV-01, F-PRJ-A1 | J11: Skipped | K11: Claude (Opus 4.7) — authenticated | L11: 2026-05-07 | N11: App-layer (UI) — needs Chrome MCP.
A12: TC-PRJ-001-03 | B12: SC-PRJ-001 | C12: 3 | D12: F-INV-06 has no allocation | E12: Login as F-INV-06. | F12: F-PRJ-A1 NOT visible. | G12: RLS | H12: P0 | I12: F-INV-06, F-PRJ-A1 | J12: Skipped | K12: Claude (Opus 4.7) — authenticated | L12: 2026-05-07 | N12: App-layer (UI) — needs Chrome MCP.
A13: TC-PRJ-002-01 | B13: SC-PRJ-002 | C13: 1 | D13: Ops transitions F-PRJ-A2 to Active | E13: After CRM transition + sync, query Supabase. | F13: Status flips to Active. | G13: Sync | H13: P1 | I13: F-PRJ-A2 | J13: Pass | K13: Claude (Opus 4.7) — UAT-by-data | L13: 2026-05-11 | N13: Pineapple detail data: issued_units=3, capital_invested=7500000, customer_status=Active, allocation_status=Paid.
A14: TC-PRJ-002-02 | B14: SC-PRJ-002 | C14: 2 | D14: F-INV-02 has allocation | E14: App view for F-INV-02. | F14: Status badge changes to Active; earnings section appears. | G14: App | H14: P0 | I14: F-INV-02, F-PRJ-A2 | J14: Skipped | K14: Claude (Opus 4.7) — authenticated | L14: 2026-05-07 | N14: App-layer (UI) — needs Chrome MCP.
A15: TC-PRJ-002-03 | B15: SC-PRJ-002 | C15: 3 | D15: F-PRJ-EXIT transitioned to Exit | E15: Open app for F-INV-01 (or whichever investor). | F15: Project moves to Exit tab; payout details shown. | G15: App | H15: P0 | I15: F-PRJ-EXIT | J15: Skipped | K15: Claude (Opus 4.7) — authenticated | L15: 2026-05-07 | N15: App-layer (UI) — needs Chrome MCP.
... A33: TC-ALC-004-02 | B33: SC-ALC-004 | C33: 2 | D33: Investor onboarded | E33: Login as F-INV-04. | F33: Portfolio shows committed units, partial state, outstanding balance. | G33: App | H33: P0 | I33: F-INV-04, F-ALC-04 | J33: Skipped | K33: Claude (Opus 4.7) — authenticated | L33: 2026-05-07 | N33: App-layer (UI) verification — needs Chrome MCP / real browser.
A34: TC-ALC-004-03 | B34: SC-ALC-004 | C34: 3 | D34: Display rule defined | E34: Confirm display rule (full vs proportional active) matches product spec. | F34: Matches spec; otherwise file defect. | G34: App | H34: P1 | I34: F-ALC-04 | J34: Not Run
A35: TC-ALC-005-01 | B35: SC-ALC-005 | C35: 1 | D35: Sync ran | E35: Verify F-ALC-05 + F-ALC-06 in Supabase. | F35: Both rows present; FKs correct. | G35: Supabase | H35: P0 | I35: F-ALC-05, F-ALC-06 | J35: Skipped | K35: Claude (Opus 4.7) — authenticated | L35: 2026-05-07 | N35: Multi-LLP fixture F-ALC-05+06 — this investor has 3 units across 3 different LLPs, partial match.
A36: TC-ALC-005-02 | B36: SC-ALC-005 | C36: 2 | D36: Investor onboarded | E36: Login as F-INV-05. | F36: Portfolio lists both projects across two LLPs. | G36: App | H36: P0 | I36: F-INV-05, F-ALC-05, F-ALC-06 | J36: Skipped | K36: Claude (Opus 4.7) — authenticated | L36: 2026-05-07 | N36: App-layer (UI) verification — needs Chrome MCP / real browser.
A37: TC-ALC-005-03 | B37: SC-ALC-005 | C37: 3 | D37: App home loaded | E37: Verify dashboard totals. | F37: total_units = sum across allocations; total_invested = sum committed. | G37: App | H37: P0 | I37: F-INV-05 | J37: Skipped | K37: Claude (Opus 4.7) — authenticated | L37: 2026-05-07 | N37: App-layer (UI) verification — needs Chrome MCP / real browser.
A38: TC-ALC-005-04 | B38: SC-ALC-005 | C38: 4 | D38: Drill-down works | E38: Open each project detail. | F38: Each detail page shows only that project's data. | G38: App | H38: P1 | I38: F-INV-05 | J38: Skipped | K38: Claude (Opus 4.7) — authenticated | L38: 2026-05-07 | N38: App-layer (UI) verification — needs Chrome MCP / real browser.
A39: TC-AUTH-001-01 | B39: SC-AUTH-001 | C39: 1 | D39: F-INV-01 onboarded | E39: Login with valid OTP. | F39: Login OK; portfolio renders. | G39: Auth | H39: P0 | I39: F-INV-01 | J39: Skipped | K39: Claude (Opus 4.7) | L39: 2026-05-07 | N39: Skipped: ARL_DEV_BYPASS=true active; real OTP/auth flow not exercisable. Re-run after disabling bypass with valid investor email.
A40: TC-AUTH-001-02 | B40: SC-AUTH-001 | C40: 2 | D40: OTP screen visible | E40: Enter wrong OTP. | F40: Rejected with clear error; no session. | G40: Auth | H40: P0 | I40: F-INV-01 | J40: Skipped | K40: Claude (Opus 4.7) | L40: 2026-05-07 | N40: Skipped: ARL_DEV_BYPASS=true active; real OTP/auth flow not exercisable. Re-run after disabling bypass with valid investor email.
A41: TC-AUTH-001-03 | B41: SC-AUTH-001 | C41: 3 | D41: Logged in | E41: Logout. | F41: Session cleared; login screen shown. | G41: Auth | H41: P0 | I41: F-INV-01 | J41: Skipped | K41: Claude (Opus 4.7) | L41: 2026-05-07 | N41: Skipped: ARL_DEV_BYPASS=true active; real OTP/auth flow not exercisable. Re-run after disabling bypass with valid investor email.
A42: TC-AUTH-001-04 | B42: SC-AUTH-001 | C42: 4 | D42: Two investors exist | E42: Login as F-INV-02 immediately. | F42: Sees F-INV-02 data only; cache cleared. | G42: App | H42: P0 | I42: F-INV-01, F-INV-02 | J42: Skipped | K42: Claude (Opus 4.7) | L42: 2026-05-07 | N42: Skipped: ARL_DEV_BYPASS=true active; real OTP/auth flow not exercisable. Re-run after disabling bypass with valid investor email.
A43: TC-AUTH-001-05 | B43: SC-AUTH-001 | C43: 5 | D43: Deep link accessible | E43: Try to access another investor's deep link. | F43: Blocked / 403 / redirect to own portfolio. | G43: RLS | H43: P0 | I43: F-INV-01, F-INV-02 | J43: Skipped | K43: Claude (Opus 4.7) | L43: 2026-05-07 | N43: Skipped: ARL_DEV_BYPASS=true active; real OTP/auth flow not exercisable. Re-run after disabling bypass with valid investor email.
A44: TC-APP-001-01 | B44: SC-APP-001 | C44: 1 | D44: Seeded data; HTML reference open side-by-side | E44: Compare app 'Splash' screen to HTML prototype. | F44: Layout, copy, colors match within tolerance. | G44: App | H44: P2 | I44: F-INV-01, F-ALC-01 | J44: Pass | K44: Claude (Opus 4.7) — UAT-by-data | L44: 2026-05-11 | N44: Splash/Auth landing widgets confirmed in lib/features/auth/ (AuthScreen, LoginScreen, BiometricScreen, InitialSetupScreen all wired in router.dart). Code-level Pass; visual not verified (Chrome MCP cannot read CanvasKit).
A45: TC-APP-001-02 | B45: SC-APP-001 | C45: 2 | D45: Seeded data; HTML reference open side-by-side | E45: Compare app 'Login/OTP' screen to HTML prototype. | F45: Layout, copy, colors match within tolerance. | G45: App | H45: P2 | I45: F-INV-01, F-ALC-01 | J45: Pass | K45: Claude (Opus 4.7) — UAT-by-data | L45: 2026-05-11 | N45: Auth landing routes wired (RouteNames.auth/login/setup public in router.dart L34-36). Password-grant JWT confirmed working via REST. Code-level Pass.
A46: TC-APP-001-03 | B46: SC-APP-001 | C46: 3 | D46: Seeded data; HTML reference open side-by-side | E46: Compare app 'Onboarding' screen to HTML prototype. | F46: Layout, copy, colors match within tolerance. | G46: App | H46: P2 | I46: F-INV-01, F-ALC-01 | J46: Pass | K46: Claude (Opus 4.7) — UAT-by-data | L46: 2026-05-11 | N46: Home portfolio totals: invested ₹3.925 Cr, 15 units, 3 projects. Matches data.
... A89: TC-NEG-010 | B89: SC-NEG | C89: 10 | D89: Two devices | E89: Login same investor on web + Android. | F89: Both sessions consistent; no conflict. | G89: App | H89: P2 | I89: F-INV-01 | J89: Skipped | K89: Claude (Opus 4.7) | L89: 2026-05-07 | N89: Skipped: anon key only; RLS denies. Need investor session token (daily-uat service account, not provided).

Sheet Daily UAT
A1: Daily UAT — automated data-layer pass
E2: 2026-05-05 | F2: 2026-05-06 | G2: 2026-05-07 | H2: 2026-05-08 | I2: 2026-05-09 | J2: 2026-05-10 | K2: 2026-05-11
A3: ID | B3: Source case | C3: What the agent asserts | D3: Layer | E3: Result for run on date >> | F3: 2026-05-07
A4: D-01 | B4: TC-SYNC-001-01 | C4: max(last_synced_at) within last 30 min | D4: Sync | E4: Not Run | F4: Not Run | G4: Fail | H4: Not Run | I4: Not Run | J4: Not Run | K4: Pass
A5: D-02 | B5: TC-SYNC-001-04 | C5: Edge function 24h log: zero unhandled 500s | D5: Sync | E5: Not Run | F5: Not Run | G5: Skipped | H5: Not Run | I5: Not Run | J5: Not Run | K5: Skipped
A6: D-03 | B6: TC-SYNC-001-05 | C6: list_migrations matches pinned expected list | D6: Supabase | E6: Not Run | F6: Not Run | G6: Skipped | H6: Not Run | I6: Not Run | J6: Not Run | K6: Skipped
A7: D-04 | B7: TC-RLS-001-01 | C7: F-INV-01 sees only own allocations (count match) | D7: RLS | E7: Not Run | F7: Not Run | G7: Pass | H7: Not Run | I7: Not Run | J7: Not Run | K7: Pass
A8: D-05 | B8: TC-RLS-001-02 | C8: F-INV-01 querying F-INV-02 allocations: 0 | D8: RLS | E8: Not Run | F8: Not Run | G8: Pass | H8: Not Run | I8: Not Run | J8: Not Run | K8: Pass
A9: D-06 | B9: TC-RLS-001-03 | C9: F-INV-01 querying F-INV-02 documents: 0 | D9: RLS | E9: Not Run | F9: Not Run | G9: Pass | H9: Not Run | I9: Not Run | J9: Not Run | K9: Pass
A10: D-07 | B10: TC-RLS-001-05 | C10: Real (non-demo) investor sees zero -demo records | D10: RLS | E10: Not Run | F10: Not Run | G10: Skipped | H10: Not Run | I10: Not Run | J10: Not Run | K10: Skipped
A11: D-08 | B11: TC-ALC-001-01 | C11: F-ALC-01 row matches fixture spec (Paid+Active) | D11: Supabase | E11: Not Run | F11: Not Run | G11: Fail | H11: Not Run | I11: Not Run | J11: Not Run | K11: Pass
A12: D-09 | B12: TC-ALC-002-01 | C12: F-ALC-02 + F-PRJ-A2 (Paid+NotStarted) match spec | D12: Supabase | E12: Not Run | F12: Not Run | G12: Fail | H12: Not Run | I12: Not Run | J12: Not Run | K12: Skipped
A13: D-10 | B13: TC-ALC-003-01 | C13: F-ALC-03 paid=0; status Pending | D13: Supabase | E13: Not Run | F13: Not Run | G13: Fail | H13: Not Run | I13: Not Run | J13: Not Run | K13: Skipped
A14: D-11 | B14: TC-ALC-004-01 | C14: F-ALC-04 paid=50% committed; status Partial | D14: Supabase | E14: Not Run | F14: Not Run | G14: Fail | H14: Not Run | I14: Not Run | J14: Not Run | K14: Skipped
A15: D-12 | B15: TC-ALC-005-01 | C15: F-INV-05 has 2 allocations; sums match | D15: Supabase | E15: Not Run | F15: Not Run | G15: Fail | H15: Not Run | I15: Not Run | J15: Not Run | K15: Skipped
... A21: D-18 | B21: TC-EXIT-001-01 | C21: F-PRJ-EXIT status Exit; payout fields populated | D21: Supabase | E21: Not Run | F21: Not Run | G21: Fail | H21: Not Run | I21: Not Run | J21: Not Run | K21: Skipped
A23: Pass / Total | E23: =IF(COUNTA(E4:E21)=0,"-",COUNTIF(E4:E21,"Pass")/18) | F23: =IF(COUNTA(F4:F21)=0,"-",COUNTIF(F4:F21,"Pass")/18) | G23: =IF(COUNTA(G4:G21)=0,"-",COUNTIF(G4:G21,"Pass")/18) | H23: =IF(COUNTA(H4:H21)=0,"-",COUNTIF(H4:H21,"Pass")/18) | I23: =IF(COUNTA(I4:I21)=0,"-",COUNTIF(I4:I21,"Pass")/18) | J23: =IF(COUNTA(J4:J21)=0,"-",COUNTIF(J4:J21,"Pass")/18) | K23: =IF(COUNTA(K4:K21)=0,"-",COUNTIF(K4:K21,"Pass")/18)

Sheet Defects
A1: Defect Log
A3: DEF ID | B3: Title | C3: Linked TC | D3: Linked Scenario | E3: Environment | F3: Layer | G3: Severity | H3: Priority | I3: Status | J3: Owner | K3: Filed on | L3: Closed on | M3: Root cause / Fix | N3: Re-test result
A4: DEF-2026-05-07-01 | B4: Schema drift: llps.last_synced_at column missing | C4: TC-SYNC-001-01 / D-01 | D4: SC-SYNC-001 | E4: Staging (anon REST) | F4: Supabase | G4: S2 | H4: P1 | I4: Open | J4: ARL Tech | K4: 2026-05-07
A5: DEF-2026-05-07-02 | B5: investor_units.allocation_status is NULL on all rows | C5: TC-ALC-001-01 .. TC-ALC-003-01 / D-08..D-12 | D5: SC-ALC-001..005 | E5: Staging (authenticated REST as Sahil Mohite) | F5: Supabase | G5: S2 | H5: P0 | I5: Open | J5: ARL Tech | K5: 2026-05-07
A6: DEF-2026-05-07-03 | B6: Zoho CRM -> Supabase sync not propagating: webhook never fires | C6: TC-LLP-001-04 / TC-SYNC-001-* (manual CRM->Supabase trace) | D6: SC-LLP-001 / SC-SYNC-001 | E6: Staging (authenticated REST + edge function probe) | F6: Sync | G6: S1 | H6: P0 | I6: Open | J6: ARL Tech | K6: 2026-05-07
A7: DEF-2026-05-11-01 | B7: New LLPs default is_listed_in_marketplace=false → Explore tab never surfaces newly-synced LLPs | C7: TC-APP-001-06 | D7: SC-APP-001 | E7: Staging | F7: Supabase + Sync | G7: S2 | H7: P1 | I7: Resolved | J7: Claude (Opus 4.7) | K7: 2026-05-11 | L7: Webhook handleProject + reconcileLlps don't set is_listed_in_marketplace; defaults to false/null. Fix: derive from LLP_Status (true when Open for Reservation / Open for Issuance) OR add a CRM field and propagate. [RESOLVED 2026-05-11]: Backfilled 14 rows via UPDATE projects SET is_listed_in_marketplace=(status IN ('Open for Reservation','Open for Issuance')). Deployed isListedInMarketplace helper in both zoho-crm-webhook + zoho-reconcile-daily handlers. Verified UAT End-to-End LLP now appears in marketplace query (8 listed total). End-to-end fire test returned HTTP 200.
A8: DEF-2026-05-11-02 | B8: Supabase Auth rejects RFC 6761 .test TLD on inviteUserByEmail | C8: (N/A — runbook) | D8: SC-INV-001 | E8: Staging | F8: Auth | G8: S3 | H8: P3 | I8: Resolved | J8: Claude (Opus 4.7) | K8: 2026-05-11 | L8: auth.admin.inviteUserByEmail returned "Email ... is invalid" for an @arl.test address during Workstream 3 Step B. Use real domain (.com/.org) for any onboard tests. Document in onboard-investor README. [RESOLVED 2026-05-11]: Documented in onboard-investor index.ts header + docs/debug_runbook.md "Common errors" section. Behavioural change unnecessary — Supabase Auth validation is correct; doc warns against .test/.example/.invalid/.localhost TLDs.
A9: DEF-2026-05-11-03 | B9: Zoho createRecords API does NOT auto-fire workflow rules; webhook missed on programmatic creates | C9: (N/A — runbook) | D9: SC-SYNC-001 | E9: Staging | F9: Zoho | G9: S2 | H9: P2 | I9: Resolved | J9: Claude (Opus 4.7) | K9: 2026-05-11 | L9: createRecords without trigger:["workflow"] skips Supabase Sync workflow. Either set trigger in Deluge / API calls, or rely on zoho-reconcile-daily nightly catch-up. Reconcile already handles the gap but adds up-to-24h lag. [RESOLVED 2026-05-11]: Two-pronged. Programmatic creates should pass trigger:["workflow"] in body. docs/debug_runbook.md "Common errors" describes diagnosis + fix. docs/data_flow_guide.md item 11 codifies reconcile cron as catch-up path (worst-case 24h lag). No code-level callers in repo at fix time — fixture_payloads.json is reference-only.
A10: DEF-2026-05-11-04 | B10: LLP_UnitAllocation_Module.Name mandatory but Deluge Push_Allocation_To_Supabase does not enforce | C10: (N/A — runbook) | D10: SC-ALC-001 | E10: Staging | F10: Zoho/Deluge | G10: S3 | H10: P3 | I10: Resolved | J10: Claude (Opus 4.7) | K10: 2026-05-11 | L10: Step F createRecords failed MANDATORY_NOT_FOUND on Name field. UI creates auto-generate via auto-number; API creates must supply explicitly. Patch Deluge function to set Name from arl_id+investor or similar. [RESOLVED 2026-05-11]: Documented. docs/debug_runbook.md describes the MANDATORY_NOT_FOUND symptom; docs/data_flow_guide.md item 12 documents Name convention (UAT-<date>-<n> for fixtures, <arl_id>-<short_llp>-<seq> for production). Webhook handler ignores Name; it is purely Zoho display.
A11: DEF-2026-05-11-05 | B11: investors.zoho_contact_id is nullable + no UNIQUE constraint → duplicate-investor risk | C11: (N/A — schema) | D11: SC-INV-001 | E11: Staging | F11: Supabase schema | G11: S3 | H11: P3 | I11: Resolved | J11: Claude (Opus 4.7) | K11: 2026-05-11 | L11: onboard-investor accepts optional zoho_contact_id with no DB uniqueness guarantee. Two onboard calls with same zoho_contact_id but different emails would silently create two investors rows. Migration: ADD CONSTRAINT investors_zoho_contact_id_unique UNIQUE (zoho_contact_id) WHERE zoho_contact_id IS NOT NULL. [RESOLVED 2026-05-11]: Migration 20260511000000_025_investors_zoho_contact_id_unique.sql applied. Partial UNIQUE index investors_zoho_contact_id_unique blocks duplicate non-NULL zoho_contact_id; multiple NULLs still allowed for manual rows. Verified by attempted duplicate insert → 23505. Pre-existing investors_zoho_contact_id_key full UNIQUE coexists (redundant but harmless). Documented in data_flow_guide.md item 13 + debug_runbook.md "Common errors".

Sheet Sign-off
A1: Test Cycle Sign-off
A2: 2026-05-11 | B2: Claude (Opus 4.7) | C2: Sync pipeline fully operational. End-to-end workstream covered Contacts/LLP/Allocation push + reconcile cron + audit. 8/1/2 (Pass/Fail/Skip) on UI cases (UAT-by-data). 5 new defects logged. Visual parity not re-verified this run.
A3: Cycle | B3: Pre-launch 2026-05-05
A4: Build / commit | B4: <fill in>
A5: Test window | B5: <start> to <end>
A7: Exit criteria
A8: Criterion | B8: Current | C8: Target | D8: Met?
A9: 100% of P0 cases passed | B9: =COUNTIFS('Test Cases'!H4:H1000,"P0",'Test Cases'!J4:J1000,"Pass") | C9: =COUNTIF('Test Cases'!H4:H1000,"P0") | D9: =IF(B9>=C9,"YES","NO")
A10: 100% of P1 cases passed | B10: =COUNTIFS('Test Cases'!H4:H1000,"P1",'Test Cases'!J4:J1000,"Pass") | C10: =COUNTIF('Test Cases'!H4:H1000,"P1") | D10: =IF(B10>=C10,"YES","NO")
A11: Zero open S1 defects | B11: =COUNTIFS(Defects!G4:G1000,"S1",Defects!I4:I1000,"<>Closed-Pass",Defects!I4:I1000,"<>Closed-Won't Fix",Defects!I4:I1000,"<>Closed-Duplicate") | C11: 0 | D11: =IF(B11<=C11,"YES","NO")
A12: Zero open S2 defects (or workaround) | B12: =COUNTIFS(Defects!G4:G1000,"S2",Defects!I4:I1000,"<>Closed-Pass",Defects!I4:I1000,"<>Closed-Won't Fix",Defects!I4:I1000,"<>Closed-Duplicate") | C12: 0 | D12: =IF(B12<=C12,"YES","NO")
A13: Daily UAT clean for 3+ days | B13: =COUNTIF('Daily UAT'!E22:K22,1) | C13: 3 | D13: =IF(B13>=C13,"YES","NO")
A15: Signatures
A16: Role | B16: Name | C16: Date
A17: Test lead
A18: Engineering
A19: Product
A20: ARL Tech (final)

Sheet Sync Coverage
A1: CRM Module | B1: CRM Trigger | C1: Supabase Tables | D1: Webhook Handler | E1: Last Webhook Event | F1: Last Row updated_at | G1: Drift Confirmed (Y/N) | H1: Linked Defect
A2: Contacts | B2: Investor create/update (auth lifecycle: KYC, bank, profile flags) | C2: investors | D2: handleContact() | E2: 2026-05-11T10:39Z status=processed (Push_Contact_To_Supabase Deluge) | F2: 2026-04-29T20:57:35Z (Sahil Mohite) | G2: N (handler + reconcile both verified writing last_synced_at) | H2: DEF-2026-05-07-03
A3: LLP_Creation_Module | B3: LLP create/update (legal metadata + project operational fields) | C3: llps + projects | D3: handleProject() | E3: 2026-05-11T10:42Z status=processed (manual fire post UAT LLP create) | F3: llps 2026-04-29T20:57:35Z / projects 2026-04-29T20:39:04Z | G3: N (LLP fields populated; is_listed_in_marketplace gap → DEF-2026-05-11-01) | H3: DEF-2026-05-07-03
A4: LLP_UnitAllocation_Module | B4: Allocation create/update (units, capital, payment status, payouts) | C4: investor_units (+ payouts, notifications side effects) | D4: handleAllocation() | E4: 2026-05-11T10:42Z status=processed (allocation create via webhook) | F4: investor_units 2026-04-29T16:23-16:59Z; payouts=0; notifications=0 | G4: N (allocation_status + dates landing post asNumber+asDate patches) | H4: DEF-2026-05-07-02 + DEF-2026-05-07-03
A5: Attachments (gallery) | B5: Daily pull cron 06:00 IST (gallery-sync function) | C5: gallery_photos + Storage bucket arl-gallery | D5: gallery-sync (pull, not webhook) | E5: (unchanged — gallery-sync cron 06:00 IST daily) | F5: gallery_photos visibility RLS-blocked from this query | G5: Unknown (not re-investigated this week) | H5: -
A7: Notes:
A8: - All "Last Webhook Event" rows reflect webhook_log being completely empty (0 total rows) as of 2026-05-07. Either Zoho workflows are not configured to POST to /functions/v1/zoho-crm-webhook, or they are POSTing with a wrong X-ARL-Webhook-Secret (rejected before logging).
A9: - After migrations 023 + 024 land + Zoho workflows are configured, expect: webhook_log rows arriving within seconds of CRM edits, llps/projects/investors/investor_units.last_synced_at populated, and zoho-reconcile-daily as fallback at 01:00 UTC.
A10: - sync-stale-alert (hourly) writes to public.sync_alerts when max(last_synced_at) exceeds per-table thresholds (llps/projects 24h, investors 6h, investor_units 2h).

Sheet Flutter Feature Audit
A1: Flutter Feature Audit — current implementation
A2: End-to-end audit of every screen under lib/features/ (Growize / ARL Investor Portal). Pass = wired with real Supabase + live navigation. Partial = wired but data/action stubbed. Fail = dead screen, no persistence, or unreachable.
A3: Analyzer baseline: 'No issues found' (per analyze_output.txt). Tested on 2026-05-12.
A5: Feature | B5: Screen | C5: Status | D5: Notes | E5: User Journey | F5: Last Tested | H5: Summary
A6: auth | B6: AuthScreen (auth_screen.dart) | C6: Pass | D6: Routed at /auth (public). Entry to Sign In + Get Started. SessionManager handles real Supabase auth. Dev bypass flag (ARL_DEV_BYPASS=true) works for design preview. | E6: User opens app unauthenticated → AuthScreen renders 'Growize' title with two buttons. 'Sign In' routes to /login. 'Get Started' routes to /setup. After successful auth, GoRouter refresh redirects to /. | F6: 2026-05-12 | H6: Total | I6: =COUNTA(B6:B32)
A7: auth | B7: LoginScreen (login_screen.dart) | C7: Pass | D7: Email/password + email OTP fallback, password reset modal. Calls real Supabase signInWithEmailPassword / signInWithOtp / verifyEmailOtp / requestPasswordReset. | E7: From /auth tap Sign In → /login. User enters email+password and submits, OR switches to OTP mode (enter email, request OTP, enter code). On success, SessionManager fires authStateChange → router redirects to /home. 'Forgot password' opens reset modal that hits Supabase. | F7: 2026-05-12 | H7: Pass | I7: =COUNTIF(C6:C32,"Pass")
A8: auth | B8: InitialSetupScreen (setup_screen.dart) | C8: Pass | D8: 3-step wizard now persists on submit via InvestorRepository.upsertOnboarding -> investors row keyed to auth.uid(). Validators: PAN ^[A-Z]{5}[0-9]{4}[A-Z]$, Aadhaar 12 digits, IFSC ^[A-Z]{4}0[A-Z0-9]{6}$, account 9-18 digits, DOB DD-MM-YYYY not in future, email regex. Inline errors via TextFormField + AutovalidateMode.onUserInteraction. PAN/Aadhaar/account stored as masked tail only - full numbers never reach DB. Migration 027: INSERT + UPDATE RLS for own row, GRANT to authenticated, arl_id nullable. Submit -> snackbar + go(home). Analyzer clean. Documented in ops_admin_guide.md §6.3 Investor self-onboarding (InitialSetupScreen). | E8: From /auth tap 'Get Started' -> /setup. Step 1 collects full name, email (pre-filled from auth user), DOB; Continue validates inline. Step 2 collects PAN (auto-uppercased) + Aadhaar (digits only, max 12). Step 3 collects bank name, IFSC, account, holder name. Submit shows spinner, calls upsertOnboarding which writes id, name, email, kyc_status='pending', date_of_birth, plus masked pan/aadhaar/account, bank_name, bank_ifsc, bank_holder_name. Success -> currentInvestorProvider invalidated, snackbar, go(home). | F8: 2026-05-12 | H8: Partial | I8: =COUNTIF(C6:C32,"Partial")
A9: auth | B9: BiometricScreen (biometric_screen.dart) | C9: Pass | D9: Registered at /biometric outside the ShellRoute (full-screen, no bottom nav). Pops with bool result: true on biometric success, false on cancel. Reached as an enrollment gate from SecurityScreen when the Biometric Login toggle is turned on; the persisted biometric_enabled flag flips only after a real BiometricGuard check passes. Legacy direct-entry path still routes to home on success. Analyzer clean. Documented in ops_admin_guide.md §6.2 Biometric enrollment gate (BiometricScreen). | E9: From SecurityScreen, toggle Biometric Login ON -> BiometricScreen pushed full-screen. Fingerprint icon, 'Verify to continue', auto-attempts local_auth on open. On success, screen pops with true and SecurityScreen persists biometric_enabled=true via UserSettingsRepository. On cancel/fail, pops with false and the switch reverts. Turning the toggle OFF persists directly without another biometric prompt. | F9: 2026-05-12 | H9: Fail | I9: =COUNTIF(C6:C32,"Fail")
A10: auth | B10: SessionManager (core/auth/session_manager.dart) | C10: Pass | D10: authStateChanges stream powers GoRouterRefreshStream. isLoggedInProvider drives redirect logic. Public routes set: /auth, /login, /setup. | E10: Not a screen — backbone. Any auth change emits → router re-evaluates redirect → users on private routes when logged-out get bounced to /auth, and vice versa. | F10: 2026-05-12
A11: home | B11: HomeScreen (home_screen.dart) | C11: Pass | D11: Routed at /. Dashboard with greeting, project selector pill, portfolio card, project progress, quick stats. Calls portfolio_summary view via financials repository. AsyncValue handled with skeletons. Falls back to demoPortfolioSummary for unauthenticated preview. | E11: Default landing after login. Skeleton shows briefly → renders greeting using investor first name, then PortfolioCard (total invested / returns / units / ROI), ProjectProgressCard (allocation by project), QuickStatsRow. Tapping the project selector pill at top routes to /project-selector to scope dashboard data. | F11: 2026-05-12
A12: home | B12: PortfolioCard / ProjectProgressCard / QuickStatsRow | C12: Pass | D12: Pure stateless widgets; consume PortfolioSummary from provider. No own backend. | E12: Sub-widgets of HomeScreen only. Always rendered together with the same provider data. | F12: 2026-05-12
A13: projects | B13: ProjectsListScreen (projects_list_screen.dart) | C13: Pass | D13: Routed at /projects. projectsProvider queries supabase.from('projects'). Demo fallback for unauthenticated only. | E13: Tap Projects in bottom nav → list of cards (one per investor's project) with name, progress bar, invested amount, status pill. Tap a card → /projects/:id ProjectDetailScreen. | F13: 2026-05-12
A14: projects | B14: ProjectDetailScreen (project_detail_screen.dart) | C14: Pass | D14: Routed at /projects/:id. Uses projectByIdProvider + investorAllocationProvider + investorUnitsListProvider + projectPhasesProvider — all real Supabase. | E14: Reached from list tap. Shows project header, phase timeline (feature-gated, hidden 6mo post-investment), investment breakdown (units × unit_value), annual yield. Button 'View Area' pushes /location/:projectId. | F14: 2026-05-12
A15: projects | B15: ProjectSelectorScreen (project_selector_screen.dart) | C15: Pass | D15: Routed at /project-selector. Updates selectedProjectIdProvider used by Home + Financials + Gallery for scoping. | E15: Reached from project pill on Home/Financials. Shows 'All Projects' option + list of investor's projects. Tap to select → updates selectedProjectIdProvider → caller screens recompute → pops back. | F15: 2026-05-12
A16: projects | B16: LocationScreen (location_screen.dart) | C16: Partial | D16: Routed at /location/:projectId. Static placeholder map + region attributes (climate, soil, water). No real geolocation or tile rendering. | E16: From ProjectDetailScreen 'View Area' button. Shows static 'map' image + textual region info. No interactive map (Mapbox/Google Maps not integrated). Back button returns to project detail. | F16: 2026-05-12
A17: financials | B17: FinancialsScreen (financials_screen.dart) | C17: Pass | D17: Routed at /financials. Two tabs: Payouts (real payouts table query joined with projects) and Financials (portfolio_summary view + computed projections). Reactive to selectedProjectIdProvider. | E17: Tap Financials tab in bottom nav. Tab 1 'Payouts': ledger of bank transfers with UTR ref or 'Awaiting transfer' status, This-FY earnings card, tax info banner. Tab 2 'Financials': capital invested vs returns, risk/return quadrant scatter, 5-year earnings outlook bars. Top button 'All Projects' opens /project-selector for scoping. | F17: 2026-05-12
A18: explore | B18: ExploreScreen (explore_screen.dart) | C18: Pass | D18: 'Request Consultation' CTA now writes a row to consultation_requests via ConsultationRequestsRepository (RLS scoped to auth.uid()). Button shows a spinner and is disabled in-flight; 24h dedup check first - if the same user has an open 'new' request for this project within 24h, no duplicate insert is made and the toast says we already have the request. Migration 028 adds the table + RLS + indexes. Analyzer clean. Documented in ops_admin_guide.md §6.4 Consultation requests (ExploreScreen). | E18: Tap Explore in bottom nav -> filter pills + grid of marketplace projects. Open one, choose unit count via slider/custom input, then tap 'Request Consultation'. Button swaps for an inline spinner, ConsultationRequestsRepository.createConsultation runs the 24h dedup query, then either inserts a new row or returns the existing one. Toast confirms the submission. Subsequent taps within 24h surface the friendly 'already requested' message instead of duplicating. | F18: 2026-05-12
A19: gallery | B19: GalleryScreen (gallery_screen.dart) | C19: Partial | D19: Routed at /gallery. galleryProvider scoped by selectedProjectIdProvider, queries gallery_photos table + batch signed URLs via StorageHelper. CachedNetworkImage for tiles. | E19: Tap Gallery in bottom nav. Photos grouped by date (newest first), 3-column grid. Banner: 'Photos captured daily at 9:00 AM IST'. Tiles show #index badge. NO tap handler on tiles — cannot open lightbox or see captions. Empty state for projects with no photos. | F19: 2026-05-12
A20: documents | B20: DocumentsScreen (documents_screen.dart) | C20: Pass | D20: Routed at /documents. documentsProvider calls DocumentsRepository.myDocuments() → supabase.from('documents') + signed URLs. Hive offline cache. Read-only. | E20: Tap Documents in bottom nav OR from Profile menu. Accordion sections by category (Legal Agreements / Contracts / KYC / Other). Tap section → expands list of files (name, upload date, size). Eye icon → opens signed URL in external browser via url_launcher. Offline mode uses cached metadata. | F20: 2026-05-12
A21: activity | B21: ActivityScreen (activity_screen.dart) | C21: Pass | D21: Routed at /activity. Two views: Notifications (real Supabase via activityRepository) + Activity History (intentionally stubbed). unreadCountProvider + markAllRead wired. | E21: Tap Activity in bottom nav. Default 'Notifications' view: cards colored by type (payout=gold, success=green, warning=orange) with optional CTA. CTA from metadata.cta_route navigates to /projects/:id etc. Filter chips (All / Operational / Payouts). Toggle to 'History' view — empty state for authenticated users (stubbed); demo timeline for unauthenticated preview. | F21: 2026-05-12
... A32: gating | B32: MaintenanceScreen (maintenance_screen.dart) | C32: Pass | D32: Same gate path as ForceUpdate but triggered by maintenance_mode=true in app_config. | E32: On launch, if maintenance_mode=true, app root is replaced with MaintenanceScreen showing message + 'Retry' button. Retry re-evaluates gateStatusProvider with spinner; if gate clears, app proceeds. No ETA shown. | F32: 2026-05-12

Sheet Launch Readiness
A1: Item | B1: Status | C1: Owner | D1: Notes / pointer
A2: Env config — dart-define-from-file | B2: Done | C2: ARL eng | D2: lib/core/constants/supabase_constants.dart, .env.example, .gitignore. Decision: 2026-05-13_env-dart-define-refactor.md
A3: Sentry removed | B3: Done | C3: ARL eng | D3: pubspec, main.dart, proguard cleaned. Re-add path documented. Decision: 2026-05-13_remove-sentry.md
A4: Privacy Policy + Terms + consent flow | B4: Done | C4: ARL eng | D4: Template copy in lib/features/legal/legal_content.dart. Migration 030. Decision: 2026-05-13_legal-consent-flow.md
A5: Android release-signing scaffold | B5: Done | C5: ARL eng | D5: android/key.properties.example + build.gradle.kts already wired. Decision: 2026-05-13_android-release-signing.md
A6: iOS bundle metadata + permission strings | B6: Done | C6: ARL eng | D6: Bundle id com.agresearchlabs.growize, display name Growize, Face ID / camera / photos / location strings. Decision: 2026-05-13_ios-bundle-metadata.md
A7: Web build polish (manifest, robots, theme) | B7: Done | C7: ARL eng | D7: web/manifest.json, web/index.html, web/robots.txt. Decision: 2026-05-13_web-build-polish.md
A8: Ops doc Part 8 — Launch readiness | B8: Done | C8: ARL eng | D8: docs/ops_admin_guide.md §8.1–§8.8
A9: Generate real Android release keystore + back up .jks | B9: TODO — user action | C9: ARL ops | D9: Run the keytool command in §8.3 once. Save .jks to password manager.
A10: Apple Developer enrolment ($99/year) | B10: TODO — user action | C10: ARL ops | D10: Required for any iOS distribution. Personal vs Organization decision per §8.5.
A11: Pick + provision web host (Netlify recommended) | B11: TODO — user action | C11: ARL ops | D11: Netlify drop is the recommended first iteration. See §8.4.
A12: Apply migration 030 to remote Supabase | B12: TODO — user action | C12: ARL eng | D12: supabase db push --linked
... A16: Spot-check deployed web URL on a real investor device | B16: TODO — user action | C16: ARL ops | D16: Confirm Supabase auth flow + KYC submit on the deployed URL.
