Workbook

Sheet Instructions
A1: ARL Growize — Investor Portal Test Cases
A3: Purpose | B3: Reusable regression checklist for the Growize Flutter app (mobile + web) and its Supabase backend. Run before each release to catch UI or backend breakage.
A4: How to use | B4: For each test, follow the Steps, then set Status (dropdown) and fill Actual Result / Tester / Date. Log defects in the last column. Filter by Priority or Type as needed.
A5: Sheets | B5: UI journeys grouped by feature, plus 'Cross-Cutting' (offline/errors/perf/security), 'Backend - DB & RLS', and 'Backend - Edge Functions & Sync'. See Dashboard for live pass/fail counts.
A6: Status values | B6: Not Run (default) · Pass · Fail · Blocked · N/A (colour-coded automatically)
A7: Priority | B7: P0 = must work / launch blocker · P1 = important · P2 = nice-to-have · P3 = edge
A8: Type | B8: UI · E2E · Backend · API · RLS · Security · Performance · Accessibility
A9: Environment | B9: Record build (web/Android/iOS), app version, Supabase project (oynfhdqizebvgmaoiuax), and tester per run.
A10: Test data tips | B10: Use a real investor with allocations for E2E; a second investor to verify RLS isolation; attach a small PDF in Zoho to validate documents-sync end-to-end.
A11: Known follow-ups | B11: BE-FN-007: apply the projects.llp_status fix to gallery-sync. DOC-011/BE-FN-002/003: need real Zoho attachments to see files flow. Repo schema baseline pending a Docker 'supabase db pull'.

Sheet Dashboard
A1: Sheet | B1: Total | C1: Not Run | D1: Pass | E1: Fail | F1: Blocked | G1: N/A | H1: % Pass
A2: Auth & Onboarding | B2: =COUNTA('Auth & Onboarding'!$A$2:$A$1000) -> 12 | C2: =COUNTIF('Auth & Onboarding'!$J$2:$J$1000,"Not Run") -> 12 | D2: =COUNTIF('Auth & Onboarding'!$J$2:$J$1000,"Pass") -> 0 | E2: =COUNTIF('Auth & Onboarding'!$J$2:$J$1000,"Fail") -> 0 | F2: =COUNTIF('Auth & Onboarding'!$J$2:$J$1000,"Blocked") -> 0 | G2: =COUNTIF('Auth & Onboarding'!$J$2:$J$1000,"N/A") -> 0 | H2: =IFERROR(D2/(B2-G2),0) -> 0
A3: Home & Portfolio | B3: =COUNTA('Home & Portfolio'!$A$2:$A$1000) -> 12 | C3: =COUNTIF('Home & Portfolio'!$J$2:$J$1000,"Not Run") -> 12 | D3: =COUNTIF('Home & Portfolio'!$J$2:$J$1000,"Pass") -> 0 | E3: =COUNTIF('Home & Portfolio'!$J$2:$J$1000,"Fail") -> 0 | F3: =COUNTIF('Home & Portfolio'!$J$2:$J$1000,"Blocked") -> 0 | G3: =COUNTIF('Home & Portfolio'!$J$2:$J$1000,"N/A") -> 0 | H3: =IFERROR(D3/(B3-G3),0) -> 0
A4: Projects | B4: =COUNTA(Projects!$A$2:$A$1000) -> 12 | C4: =COUNTIF(Projects!$J$2:$J$1000,"Not Run") -> 12 | D4: =COUNTIF(Projects!$J$2:$J$1000,"Pass") -> 0 | E4: =COUNTIF(Projects!$J$2:$J$1000,"Fail") -> 0 | F4: =COUNTIF(Projects!$J$2:$J$1000,"Blocked") -> 0 | G4: =COUNTIF(Projects!$J$2:$J$1000,"N/A") -> 0 | H4: =IFERROR(D4/(B4-G4),0) -> 0
A5: Financials | B5: =COUNTA(Financials!$A$2:$A$1000) -> 9 | C5: =COUNTIF(Financials!$J$2:$J$1000,"Not Run") -> 9 | D5: =COUNTIF(Financials!$J$2:$J$1000,"Pass") -> 0 | E5: =COUNTIF(Financials!$J$2:$J$1000,"Fail") -> 0 | F5: =COUNTIF(Financials!$J$2:$J$1000,"Blocked") -> 0 | G5: =COUNTIF(Financials!$J$2:$J$1000,"N/A") -> 0 | H5: =IFERROR(D5/(B5-G5),0) -> 0
A6: Documents | B6: =COUNTA(Documents!$A$2:$A$1000) -> 12 | C6: =COUNTIF(Documents!$J$2:$J$1000,"Not Run") -> 12 | D6: =COUNTIF(Documents!$J$2:$J$1000,"Pass") -> 0 | E6: =COUNTIF(Documents!$J$2:$J$1000,"Fail") -> 0 | F6: =COUNTIF(Documents!$J$2:$J$1000,"Blocked") -> 0 | G6: =COUNTIF(Documents!$J$2:$J$1000,"N/A") -> 0 | H6: =IFERROR(D6/(B6-G6),0) -> 0
A7: Activity & Gallery | B7: =COUNTA('Activity & Gallery'!$A$2:$A$1000) -> 9 | C7: =COUNTIF('Activity & Gallery'!$J$2:$J$1000,"Not Run") -> 9 | D7: =COUNTIF('Activity & Gallery'!$J$2:$J$1000,"Pass") -> 0 | E7: =COUNTIF('Activity & Gallery'!$J$2:$J$1000,"Fail") -> 0 | F7: =COUNTIF('Activity & Gallery'!$J$2:$J$1000,"Blocked") -> 0 | G7: =COUNTIF('Activity & Gallery'!$J$2:$J$1000,"N/A") -> 0 | H7: =IFERROR(D7/(B7-G7),0) -> 0
A8: Explore & Exit | B8: =COUNTA('Explore & Exit'!$A$2:$A$1000) -> 8 | C8: =COUNTIF('Explore & Exit'!$J$2:$J$1000,"Not Run") -> 8 | D8: =COUNTIF('Explore & Exit'!$J$2:$J$1000,"Pass") -> 0 | E8: =COUNTIF('Explore & Exit'!$J$2:$J$1000,"Fail") -> 0 | F8: =COUNTIF('Explore & Exit'!$J$2:$J$1000,"Blocked") -> 0 | G8: =COUNTIF('Explore & Exit'!$J$2:$J$1000,"N/A") -> 0 | H8: =IFERROR(D8/(B8-G8),0) -> 0
A9: Profile & Settings | B9: =COUNTA('Profile & Settings'!$A$2:$A$1000) -> 7 | C9: =COUNTIF('Profile & Settings'!$J$2:$J$1000,"Not Run") -> 7 | D9: =COUNTIF('Profile & Settings'!$J$2:$J$1000,"Pass") -> 0 | E9: =COUNTIF('Profile & Settings'!$J$2:$J$1000,"Fail") -> 0 | F9: =COUNTIF('Profile & Settings'!$J$2:$J$1000,"Blocked") -> 0 | G9: =COUNTIF('Profile & Settings'!$J$2:$J$1000,"N/A") -> 0 | H9: =IFERROR(D9/(B9-G9),0) -> 0
A10: Support | B10: =COUNTA(Support!$A$2:$A$1000) -> 5 | C10: =COUNTIF(Support!$J$2:$J$1000,"Not Run") -> 5 | D10: =COUNTIF(Support!$J$2:$J$1000,"Pass") -> 0 | E10: =COUNTIF(Support!$J$2:$J$1000,"Fail") -> 0 | F10: =COUNTIF(Support!$J$2:$J$1000,"Blocked") -> 0 | G10: =COUNTIF(Support!$J$2:$J$1000,"N/A") -> 0 | H10: =IFERROR(D10/(B10-G10),0) -> 0
A11: Cross-Cutting (UX-Perf-Sec) | B11: =COUNTA('Cross-Cutting (UX-Perf-Sec)'!$A$2:$A$1000) -> 12 | C11: =COUNTIF('Cross-Cutting (UX-Perf-Sec)'!$J$2:$J$1000,"Not Run") -> 12 | D11: =COUNTIF('Cross-Cutting (UX-Perf-Sec)'!$J$2:$J$1000,"Pass") -> 0 | E11: =COUNTIF('Cross-Cutting (UX-Perf-Sec)'!$J$2:$J$1000,"Fail") -> 0 | F11: =COUNTIF('Cross-Cutting (UX-Perf-Sec)'!$J$2:$J$1000,"Blocked") -> 0 | G11: =COUNTIF('Cross-Cutting (UX-Perf-Sec)'!$J$2:$J$1000,"N/A") -> 0 | H11: =IFERROR(D11/(B11-G11),0) -> 0
A12: Backend - DB & RLS | B12: =COUNTA('Backend - DB & RLS'!$A$2:$A$1000) -> 13 | C12: =COUNTIF('Backend - DB & RLS'!$J$2:$J$1000,"Not Run") -> 13 | D12: =COUNTIF('Backend - DB & RLS'!$J$2:$J$1000,"Pass") -> 0 | E12: =COUNTIF('Backend - DB & RLS'!$J$2:$J$1000,"Fail") -> 0 | F12: =COUNTIF('Backend - DB & RLS'!$J$2:$J$1000,"Blocked") -> 0 | G12: =COUNTIF('Backend - DB & RLS'!$J$2:$J$1000,"N/A") -> 0 | H12: =IFERROR(D12/(B12-G12),0) -> 0
A13: Backend - Edge Functions & Sync | B13: =COUNTA('Backend - Edge Functions & Sync'!$A$2:$A$1000) -> 16 | C13: =COUNTIF('Backend - Edge Functions & Sync'!$J$2:$J$1000,"Not Run") -> 16 | D13: =COUNTIF('Backend - Edge Functions & Sync'!$J$2:$J$1000,"Pass") -> 0 | E13: =COUNTIF('Backend - Edge Functions & Sync'!$J$2:$J$1000,"Fail") -> 0 | F13: =COUNTIF('Backend - Edge Functions & Sync'!$J$2:$J$1000,"Blocked") -> 0 | G13: =COUNTIF('Backend - Edge Functions & Sync'!$J$2:$J$1000,"N/A") -> 0 | H13: =IFERROR(D13/(B13-G13),0) -> 0
A14: TOTAL | B14: =SUM(B2:B13) -> 127 | C14: =SUM(C2:C13) -> 127 | D14: =SUM(D2:D13) -> 0 | E14: =SUM(E2:E13) -> 0 | F14: =SUM(F2:F13) -> 0 | G14: =SUM(G2:G13) -> 0 | H14: =IFERROR(D14/(B14-G14),0) -> 0

Sheet User Flows
A1: Flow ID | B1: Journey | C1: Step | D1: Screen / Surface | E1: User Action | F1: System / Backend | G1: Expected Outcome | H1: Linked Test IDs
A2: FLOW-A | B2: First launch & authentication | C2: 1 | D2: Launch / boot | E2: Open app | F2: Supabase + Hive init; gate check | G2: App boots; gate evaluated | H2: AUTH-005, XC-006
C3: 2 | D3: Version/maintenance gate | E3: (automatic) | F3: latest-app-version compare | G3: Force-update or maintenance screen if applicable, else continue | H3: XC-006, XC-007, BE-FN-015
C4: 3 | D4: App lock | E4: Resume / idle return | F4: Biometric or PIN | G4: Lock enforced when enabled; content hidden until unlock | H4: AUTH-008
C5: 4 | D5: Auth check | E5: (automatic) | F5: Session check | G5: Signed in → Home; otherwise → Demo browsing | H5: AUTH-005
C6: 5 | D6: Sign in | E6: Enter email | F6: request-auth-email | G6: Auth email / code sent; no enumeration leak | H6: AUTH-001, BE-FN-014
C7: 6 | D7: Verify | E7: Enter OTP / open link | F7: Supabase auth | G7: Valid → session; invalid → inline error | H7: AUTH-002, AUTH-003
C8: 7 | D8: Post-auth | E8: (automatic) | F8: Providers invalidate | G8: Real data replaces demo; lands on Home | H8: AUTH-010, AUTH-012, XC-004
A9: FLOW-B | B9: Demo → authenticated | C9: 1 | D9: Demo browse | E9: Browse tabs logged out | F9: Demo persona (client-side) | G9: Sample data + 'Sample' badges; no real data | H9: AUTH-005, HOME-010
C10: 2 | D10: Sign in | E10: (see FLOW-A) | F10: request-auth-email + verify | G10: Session established | H10: AUTH-001, AUTH-002
C11: 3 | D11: Transition | E11: (automatic) | F11: Invalidate user-scoped caches | G11: No demo/real data mix afterwards | H11: AUTH-012, XC-004
A12: FLOW-C | B12: Portfolio → project → documents | C12: 1 | D12: Home | E12: View dashboard | F12: scopedPortfolio + projects | G12: Totals + contract progress correct and in sync | H12: HOME-001, HOME-002, HOME-003
C13: 2 | D13: Select project | E13: Tap selector | F13: Rescope providers | G13: Portfolio + financials scope to project | H13: HOME-004, FIN-007
C14: 3 | D14: Projects list | E14: Open Projects tab | F14: projectsProvider | G14: Grid renders / empty state / Retry card | H14: PROJ-001, PROJ-002, PROJ-003
C15: 4 | D15: Project detail | E15: Tap a tile | F15: projectById + phases/updates/allocation/docs | G15: Full detail; not-found and error handled gracefully | H15: PROJ-004, PROJ-005, PROJ-006, PROJ-007
C16: 5 | D16: Documents | E16: Open Documents | F16: documents + project_documents (RLS) | G16: Three sections render; RLS isolates per investor | H16: DOC-001, DOC-002, DOC-003, DOC-004
C17: 6 | D17: Open document | E17: Tap a document | F17: Signed URL → in-app viewer | G17: Opens; or 'Not available yet' if file missing | H17: DOC-005, DOC-006
A18: FLOW-D | B18: Financials & payouts | C18: 1 | D18: Financials | E18: Open tab | F18: scopedPortfolio + payouts | G18: Summary cards + payouts ledger | H18: FIN-001, FIN-002
C19: 2 | D19: Empty / error | E19: (conditions) | F19: Provider state | G19: Empty state or Retry card (never blank/spinner-forever) | H19: FIN-003, FIN-004, FIN-005
C20: 3 | D20: FY earned | E20: View | F20: Compute Apr–Mar window | G20: Correct FY-earned total | H20: FIN-006
C21: 4 | D21: Scope | E21: Select a project | F21: Rescope | G21: Scoped totals + ledger | H21: FIN-007
A22: FLOW-E | B22: Documents data sync (E2E) | C22: 1 | D22: Upload in Zoho | E22: Ops attaches PDF | F22: LLP / Contact attachment | G22: File staged on the Zoho record | H22: DOC-011
C23: 2 | D23: Sync trigger | E23: Cron 06:15 IST / manual | F23: documents-sync (shared secret) | G23: Auth ok; scans projects + investors | H23: BE-FN-001, BE-FN-006
C24: 3 | D24: Store bytes | E24: (automatic) | F24: Upload to arl-documents | G24: Objects at project/<id> and investor/<id> | H24: BE-FN-002, BE-FN-003
C25: 4 | D25: Catalog rows | E25: (automatic) | F25: Upsert tables | G25: project_documents / documents rows; idempotent (no dupes) | H25: BE-FN-004, BE-DB-010
C26: 5 | D26: Notify + log | E26: (automatic) | F26: webhook_log + notifications | G26: Run logged 'processed'; investors notified | H26: BE-FN-005
C27: 6 | D27: Appears in app | E27: Refresh app | F27: Signed URL | G27: File shows in correct section and opens | H27: DOC-011, BE-FN-016
A28: FLOW-F | B28: Exit request | C28: 1 | D28: Exit eligibility | E28: Open Exit | F28: Eligibility providers | G28: Lock-in / earliest-unit / grid; neutral placeholders if absent | H28: EXIT-001, EXIT-003
C29: 2 | D29: Request | E29: Submit exit | F29: exit_requests (edge-only write) | G29: Pending state surfaced | H29: EXIT-002
C30: 3 | D30: Settlement | E30: (backend) | F30: Settle + notify | G30: 'Exit settled' notification delivered | H30: EXIT-004
A31: FLOW-G | B31: Support ticket | C31: 1 | D31: Support | E31: Open Support | F31: Static + tickets | G31: Screen + WhatsApp CTA | H31: SUP-001
C32: 2 | D32: Create ticket | E32: Submit | F32: create-ticket (JWT) | G32: Ticket listed + first-message notification | H32: SUP-002, BE-FN-011
C33: 3 | D33: Reply | E33: Submit reply | F33: reply-ticket (JWT) | G33: Thread updates | H33: SUP-003
C34: 4 | D34: View thread | E34: Open ticket | F34: - | G34: Messages render in order with status | H34: SUP-004
A35: FLOW-H | B35: Profile / bank / KYC | C35: 1 | D35: Profile | E35: Open Profile | F35: currentInvestor + portfolio | G35: Name/email; sensible loading fallback | H35: PROF-001
C36: 2 | D36: KYC | E36: Open / resubmit | F36: KYC record | G36: Status correct; resubmission + notification | H36: PROF-002
C37: 3 | D37: Bank change | E37: Submit change | F37: bank-change-request + notify-bank-update | G37: Confirmation; NO direct client DB write | H37: PROF-003, BE-FN-012
C38: 4 | D38: Settings | E38: Toggle options | F38: user_settings | G38: App lock / biometric / prefs persist | H38: SET-001, SET-003
A39: FLOW-I | B39: Offline & error resilience (cross-cutting) | C39: 1 | D39: Any screen offline | E39: Lose connectivity | F39: Hive cache | G39: Last-known data renders; sync badge reflects state | H39: XC-002
C40: 2 | D40: Fetch fails | E40: (condition) | F40: Provider error/empty | G40: Empty or Retry card — never blank or endless skeleton | H40: HOME-012, PROJ-003, FIN-004, DOC-007
...

Sheet Auth & Onboarding
A1: Test ID | B1: Area | C1: Scenario | D1: Priority | E1: Preconditions | F1: Test Steps | G1: Test Data | H1: Expected Result | I1: Type | J1: Status | K1: Actual Result | L1: Tester | M1: Date | N1: Defect / Notes
A2: AUTH-001 | B2: Auth | C2: Request login email with a valid registered email | D2: P0 | E2: App installed; valid investor email exists | F2: 1. Open app, tap Sign In 2. Enter registered email 3. Submit | G2: Registered investor email | H2: request-auth-email fires; user sees 'check your email / enter code' screen; no error | I2: E2E | J2: Not Run
A3: AUTH-002 | B3: Auth | C3: Complete auth with valid OTP/magic link | D3: P0 | E3: AUTH-001 done | F3: 1. Enter the OTP / open magic link 2. Confirm | G3: Valid code | H3: Session established; lands on Home with real (non-demo) data | I3: E2E | J3: Not Run
A4: AUTH-003 | B4: Auth | C4: Reject invalid / expired OTP | D4: P1 | E4: AUTH-001 done | F4: 1. Enter wrong or expired code | G4: 000000 | H4: Clear inline error; no session created; user stays on auth screen | I4: UI | J4: Not Run
A5: AUTH-004 | B5: Auth | C5: Unregistered email handling | D5: P1 | E5: - | F5: 1. Enter email with no investor record | G5: unknown@x.com | H5: Graceful message; no crash; no account leak of whether email exists | I5: Security | J5: Not Run
A6: AUTH-005 | B6: Auth | C6: Unauthenticated browsing shows DEMO data | D6: P0 | E6: Logged out | F6: 1. Open app without signing in 2. Browse Home/Projects/Financials | G6: - | H6: Demo persona data shows with 'Sample' badges + demo banner; never real investor data | I6: UI | J6: Not Run
A7: AUTH-006 | B7: Onboarding | C7: First-time self-onboard flow | D7: P1 | E7: New user | F7: 1. Complete onboarding/self-onboard steps | G7: New profile | H7: Profile created; routed to Home; no duplicate investor row | I7: E2E | J7: Not Run
A8: AUTH-007 | B8: Auth | C8: Biometric enrolment screen | D8: P1 | E8: Device has biometrics | F8: 1. Go to setup biometric 2. Enrol | G8: - | H8: Biometric enabled; stored securely; toggle reflects state | I8: UI | J8: Not Run
A9: AUTH-008 | B9: Auth | C9: App lock triggers on resume after background/idle | D9: P0 | E9: App lock enabled | F9: 1. Background app / wait idle 2. Reopen | G9: - | H9: Lock screen shown; unlock via biometric/PIN; content hidden until unlock | I9: Security | J9: Not Run
A10: AUTH-009 | B10: Auth | C10: Web session idle expiry signs out | D10: P1 | E10: Web build, logged in | F10: 1. Leave idle past timeout 2. Return | G10: - | H10: Session expired → signed out + web session cleared; redirected to auth | I10: Security | J10: Not Run
A11: AUTH-010 | B11: Auth | C11: Sign out clears session and user-scoped caches | D11: P0 | E11: Logged in | F11: 1. Profile → Sign out | G11: - | H11: Session ended; portfolio/projects/docs/notifications/gallery caches invalidated; demo/login screen shown | I11: E2E | J11: Not Run
A12: AUTH-011 | B12: Onboarding | C12: Guided tour highlights correct widgets | D12: P2 | E12: First login | F12: 1. Trigger tour | G12: - | H12: Tour overlay points at Portfolio card, Progress card, Quick stats, Projects grid via TourKeys; skippable | I12: UI | J12: Not Run
A13: AUTH-012 | B13: Auth | C13: Provider refetch on auth state change | D13: P0 | E13: Was browsing demo, then sign in | F13: 1. Sign in from demo browsing | G13: - | H13: All user-scoped providers re-fetch real data; demo data fully replaced (no stale mix) | I13: E2E | J13: Not Run

Sheet Home & Portfolio
A1: Test ID | B1: Area | C1: Scenario | D1: Priority | E1: Preconditions | F1: Test Steps | G1: Test Data | H1: Expected Result | I1: Type | J1: Status | K1: Actual Result | L1: Tester | M1: Date | N1: Defect / Notes
A2: HOME-001 | B2: Home | C2: Portfolio summary card totals correct | D2: P0 | E2: Logged in with allocations | F2: 1. Open Home | G2: Investor with units | H2: Total value, invested, returns, active units match backing data; INR formatted | I2: E2E | J2: Not Run
A3: HOME-002 | B3: Home | C3: Contract Progress (single project) % = Month X of Y | D3: P0 | E3: One project selected | F3: 1. Select a project 2. View Contract Progress card | G3: launch_year set | H3: Percent = months elapsed / total months (e.g. 9/60 = 15%); bar fill matches the % and the 'Month X of Y' label | I3: UI | J3: Not Run
A4: HOME-003 | B4: Home | C4: Contract Progress (all projects) each mini bar in sync | D4: P0 | E4: ≥2 projects, 'All Projects' | F4: 1. Clear selection 2. View stacked progress bars | G4: Multiple projects | H4: Each row's %, bar fill and 'Month X of Y' agree; no 0% where months have elapsed | I4: UI | J4: Not Run
A5: HOME-004 | B5: Home | C5: Project selector rescopes portfolio + progress | D5: P1 | E5: ≥2 projects | F5: 1. Pick one project in selector | G5: - | H5: Totals + progress filter to that project; greeting/name unchanged | I5: UI | J5: Not Run
A6: HOME-005 | B6: Home | C6: Long investor name does not overflow greeting | D6: P1 | E6: Investor with long multi-word name | F6: 1. Open Home | G6: 'Test Person Test Last' | H6: Only first name shown in greeting; selector pill not pushed off-screen | I6: UI | J6: Not Run
A7: HOME-006 | B7: Home | C7: Pending project shows on-hold messaging | D7: P1 | E7: Project status contains 'pending' | F7: 1. View its progress card | G7: Pending project | H7: Shows 'Awaiting payment clearance' + 'Payouts on hold' pill; not a misleading % | I7: UI | J7: Not Run
A8: HOME-007 | B8: Home | C8: Empty state when no projects | D8: P0 | E8: Logged in, zero allocations | F8: 1. Open Home | G8: No units | H8: Actionable 'No projects yet — allocations appear once they sync'; NOT an infinite spinner | I8: UI | J8: Not Run
A9: HOME-008 | B9: Home | C9: Cold-start loading skeleton then resolves | D9: P1 | E9: Fresh launch | F9: 1. Launch app | G9: - | H9: Skeleton shows briefly, then real data; skeleton never persists indefinitely | I9: UI | J9: Not Run
A10: HOME-009 | B10: Home | C10: Quick stats row values correct | D10: P1 | E10: Logged in | F10: 1. View quick stats | G10: - | H10: Active/Earned/Pending values match portfolio summary | I10: UI | J10: Not Run
A11: HOME-010 | B11: Home | C11: Demo banner + Sample badges (unauthenticated) | D11: P2 | E11: Logged out | F11: 1. Browse Home | G11: - | H11: Demo banner visible; cards show 'Sample' badge | I11: UI | J11: Not Run
A12: HOME-011 | B12: Home | C12: Refresh updates values | D12: P1 | E12: Logged in | F12: 1. Pull to refresh / re-enter | G12: - | H12: Latest data fetched; UI updates without restart | I12: UI | J12: Not Run
A13: HOME-012 | B13: Home | C13: Error fallback when portfolio fails with no cache | D13: P0 | E13: Force network failure, no cache | F13: 1. Open Home offline on first run | G13: - | H13: Friendly 'couldn't load / Retry' card (not blank, not skeleton-forever); Retry re-fetches | I13: UI | J13: Not Run

Sheet Projects
A1: Test ID | B1: Area | C1: Scenario | D1: Priority | E1: Preconditions | F1: Test Steps | G1: Test Data | H1: Expected Result | I1: Type | J1: Status | K1: Actual Result | L1: Tester | M1: Date | N1: Defect / Notes
A2: PROJ-001 | B2: Projects | C2: Projects list grid renders tiles | D2: P0 | E2: Logged in w/ projects | F2: 1. Go to Projects tab | G2: - | H2: 2-col grid; each tile: hero image, status pill, tier badge, units, invested, progress bar, next payout | I2: UI | J2: Not Run
A3: PROJ-002 | B3: Projects | C3: Empty state when no projects | D3: P0 | E3: Zero allocations | F3: 1. Open Projects | G3: - | H3: 'No projects yet.' shown; no spinner-forever | I3: UI | J3: Not Run
A4: PROJ-003 | B4: Projects | C4: Error fallback on list fetch failure | D4: P0 | E4: Force failure, no cache | F4: 1. Open Projects | G4: - | H4: Friendly Retry card; tapping Retry re-queries projectsProvider | I4: UI | J4: Not Run
A5: PROJ-004 | B5: Projects | C5: Project detail loads full tree | D5: P0 | E5: Tap a project | F5: 1. Open a project tile | G5: - | H5: Header, status, contract progress, phase timeline, monthly updates, allocation, documents row render | I5: E2E | J5: Not Run
A6: PROJ-005 | B6: Projects | C6: Project not found handling | D6: P1 | E6: Invalid/removed project id | F6: 1. Deep-link bad id | G6: bad-uuid | H6: 'Project not found' message; no crash | I6: UI | J6: Not Run
A7: PROJ-006 | B7: Projects | C7: Detail error fallback (not infinite spinner) | D7: P1 | E7: Force detail fetch error | F7: 1. Open detail offline | G7: - | H7: Friendly Retry card with back access; NOT a permanent spinner | I7: UI | J7: Not Run
A8: PROJ-007 | B8: Projects | C8: Phase timeline reflects done/current/pending | D8: P1 | E8: Project with phases | F8: 1. View timeline | G8: Seeded phases | H8: Correct states + started/completed dates; falls back to schedule from start date if no rows | I8: UI | J8: Not Run
A9: PROJ-008 | B9: Projects | C9: Monthly updates list | D9: P2 | E9: Project with updates | F9: 1. Scroll updates | G9: - | H9: Updates render newest first; empty-state copy when none | I9: UI | J9: Not Run
A10: PROJ-009 | B10: Projects | C10: Allocation shows summed issued units | D10: P1 | E10: Investor with ≥2 allocation rows same project | F10: 1. View units | G10: Multiple unit rows | H10: Units summed (not first only); matches financials | I10: UI | J10: Not Run
A11: PROJ-010 | B11: Projects | C11: Tile progress == detail progress | D11: P1 | E11: Any project | F11: 1. Compare tile bar vs detail | G11: - | H11: Same % on both surfaces | I11: UI | J11: Not Run
A12: PROJ-011 | B12: Projects | C12: Location screen never exposes raw coordinates | D12: P0 | E12: Project detail | F12: 1. Open location/area | G12: - | H12: Approx area only; no latitude/longitude in payload (projects_public view) | I12: Security | J12: Not Run
A13: PROJ-012 | B13: Projects | C13: Project photos screen | D13: P2 | E13: Project w/ gallery | F13: 1. Open photos | G13: - | H13: Photos load via signed URLs; graceful empty/error | I13: UI | J13: Not Run

Sheet Financials
A1: Test ID | B1: Area | C1: Scenario | D1: Priority | E1: Preconditions | F1: Test Steps | G1: Test Data | H1: Expected Result | I1: Type | J1: Status | K1: Actual Result | L1: Tester | M1: Date | N1: Defect / Notes
A2: FIN-001 | B2: Financials | C2: Portfolio summary cards render | D2: P0 | E2: Logged in | F2: 1. Open Financials | G2: - | H2: Total invested, returns, FY-earned cards correct + INR formatted | I2: E2E | J2: Not Run
A3: FIN-002 | B3: Financials | C3: Payouts ledger lists transactions | D3: P0 | E3: Investor with payouts | F3: 1. Scroll ledger | G3: - | H3: Transactions listed newest first; processed vs pending distinguished | I3: UI | J3: Not Run
A4: FIN-003 | B4: Financials | C4: Empty ledger state | D4: P1 | E4: No payouts | F4: 1. Open ledger | G4: - | H4: 'No transactions yet' empty state (not blank) | I4: UI | J4: Not Run
A5: FIN-004 | B5: Financials | C5: Portfolio cards error fallback | D5: P1 | E5: Force failure | F5: 1. Open offline | G5: - | H5: Friendly Retry card (NOT a silent skeleton); Retry re-fetches scopedPortfolio | I5: UI | J5: Not Run
A6: FIN-005 | B6: Financials | C6: Payouts error fallback | D6: P1 | E6: Force failure | F6: 1. Open offline | G6: - | H6: Friendly Retry card for ledger; Retry re-fetches payouts | I6: UI | J6: Not Run
A7: FIN-006 | B7: Financials | C7: FY window calculation (Apr–Mar) | D7: P1 | E7: Payouts across FY boundary | F7: 1. Check FY-earned total | G7: Payouts before/after Apr 1 | H7: Only processed payouts after FY start counted | I7: Backend | J7: Not Run
A8: FIN-007 | B8: Financials | C8: Scope by selected project | D8: P1 | E8: ≥2 projects | F8: 1. Select project on Home 2. Open Financials | G8: - | H8: Totals + ledger scoped to selection | I8: UI | J8: Not Run
A9: FIN-008 | B9: Financials | C9: Demo financials when unauthenticated | D9: P2 | E9: Logged out | F9: 1. Browse Financials | G9: - | H9: Demo payouts/summary with Sample badges | I9: UI | J9: Not Run
A10: FIN-009 | B10: Financials | C10: Amounts never show raw/incorrect rounding | D10: P2 | E10: Various amounts | F10: 1. Inspect formatting | G10: ₹ values | H10: Consistent INR formatting; no floating-point artifacts | I10: UI | J10: Not Run

Sheet Documents
A1: Test ID | B1: Area | C1: Scenario | D1: Priority | E1: Preconditions | F1: Test Steps | G1: Test Data | H1: Expected Result | I1: Type | J1: Status | K1: Actual Result | L1: Tester | M1: Date | N1: Defect / Notes
A2: DOC-001 | B2: Documents | C2: Three sections render (Common / My Projects / My Documents) | D2: P0 | E2: Logged in | F2: 1. Open Documents | G2: - | H2: Section headers always show; counts per section correct | I2: UI | J2: Not Run
A3: DOC-002 | B3: Documents | C3: Common docs visible to every authenticated investor | D3: P0 | E3: Common doc exists | F3: 1. View Common section | G3: common/* doc | H3: Common docs listed for any logged-in user | I3: RLS | J3: Not Run
A4: DOC-003 | B4: Documents | C4: Project docs visible only with allocation | D4: P0 | E4: Investor A has units, B does not | F4: 1. Compare both users' project docs | G4: project_documents rows | H4: A sees the project's docs; B does not | I4: RLS | J4: Not Run
A5: DOC-004 | B5: Documents | C5: Personal docs visible to owner only | D5: P0 | E5: Investor-tier doc for A | F5: 1. Login as B | G5: investor/<A>/* doc | H5: B cannot see or open A's personal doc | I5: RLS | J5: Not Run
A6: DOC-005 | B6: Documents | C6: Open document with uploaded file | D6: P0 | E6: Doc row + file in arl-documents | F6: 1. Tap a document | G6: Real uploaded PDF | H6: Opens in in-app viewer; screenshot prevention active | I6: E2E | J6: Not Run
A7: DOC-006 | B7: Documents | C7: Missing-file document shows 'Not available yet' | D7: P0 | E7: Doc row exists, file NOT uploaded | F7: 1. Tap that document | G7: Row w/ empty signed URL | H7: Row dimmed + 'Not available yet' + clock icon; tap shows friendly message (NOT broken /storage/v1null tab) | I7: UI | J7: Not Run
A8: DOC-007 | B8: Documents | C8: Personal docs error fallback | D8: P1 | E8: Force failure | F8: 1. Open offline | G8: - | H8: Friendly Retry card for personal section; Retry re-fetches | I8: UI | J8: Not Run
A9: DOC-008 | B9: Documents | C9: Empty states per section + overall | D9: P1 | E9: Some sections empty | F9: 1. View | G9: - | H9: 'No documents in this section yet' per empty accordion; overall 'No documents yet' when all empty | I9: UI | J9: Not Run
A10: DOC-009 | B10: Documents | C10: Offline cached list renders | D10: P1 | E10: Previously loaded, now offline | F10: 1. Reopen offline | G10: - | H10: Last-known list shows from Hive; open may show 'not available' if URL expired | I10: UI | J10: Not Run
A11: DOC-010 | B11: Documents | C11: Signed URL expiry refresh | D11: P2 | E11: Wait > URL TTL | F11: 1. Reopen and tap doc | G11: - | H11: Fresh signed URL generated; opens (no stale-URL failure) | I11: Backend | J11: Not Run
A12: DOC-011 | B12: Documents | C12: E2E: Zoho attachment → appears in app | D12: P0 | E12: documents-sync deployed | F12: 1. Attach PDF to Zoho LLP/Contact 2. Run sync / wait for cron 3. Refresh app | G12: Zoho attachment | H12: File appears in correct section and opens | I12: E2E | J12: Not Run
A13: DOC-012 | B13: Documents | C13: Viewer back navigation | D13: P2 | E13: In viewer | F13: 1. Tap back | G13: - | H13: Returns to Documents list; no stuck state | I13: UI | J13: Not Run

Sheet Activity & Gallery
A1: Test ID | B1: Area | C1: Scenario | D1: Priority | E1: Preconditions | F1: Test Steps | G1: Test Data | H1: Expected Result | I1: Type | J1: Status | K1: Actual Result | L1: Tester | M1: Date | N1: Defect / Notes
A2: ACT-001 | B2: Activity | C2: Notifications list renders | D2: P0 | E2: Investor with notifications | F2: 1. Open Activity | G2: - | H2: Notifications listed newest first; types (document/photo/payout/life-event) render correctly | I2: UI | J2: Not Run
A3: ACT-002 | B3: Activity | C3: Unread count badge accurate | D3: P1 | E3: Some unread | F3: 1. Check bottom nav / header badge | G3: - | H3: Badge matches unread count; 0 when none | I3: UI | J3: Not Run
A4: ACT-003 | B4: Activity | C4: Mark all read | D4: P1 | E4: Unread exist | F4: 1. Tap mark all read | G4: - | H4: All become read; badge clears; persists after refresh | I4: UI | J4: Not Run
A5: ACT-004 | B5: Activity | C5: Empty + error states | D5: P1 | E5: None / forced error | F5: 1. Open Activity | G5: - | H5: 'You're all caught up' when empty; AsyncValueWidget Retry on error | I5: UI | J5: Not Run
A6: ACT-005 | B6: Activity | C6: Notification deep-link | D6: P2 | E6: Notification with target | F6: 1. Tap a notification | G6: - | H6: Routes to relevant screen (e.g. project, document) | I6: UI | J6: Not Run
A7: GAL-001 | B7: Gallery | C7: Grid grouped by date with signed URLs | D7: P0 | E7: Project has photos | F7: 1. Open Gallery | G7: - | H7: Photos grouped by date; thumbnails load via signed URLs | I7: UI | J7: Not Run
A8: GAL-002 | B8: Gallery | C8: Empty + error states | D8: P1 | E8: No photos / forced error | F8: 1. Open Gallery | G8: - | H8: Empty-state copy; Retry card on error | I8: UI | J8: Not Run
A9: GAL-003 | B9: Gallery | C9: Lightbox / full image | D9: P2 | E9: Photos present | F9: 1. Tap a photo | G9: - | H9: Full image opens; swipe; close | I9: UI | J9: Not Run
A10: GAL-004 | B10: Gallery | C10: New-photo notification on sync | D10: P2 | E10: gallery-sync adds photos | F10: 1. Run sync | G10: - | H10: Investors in project get 'New farm photos' notification | I10: E2E | J10: Not Run

Sheet Explore & Exit
A1: Test ID | B1: Area | C1: Scenario | D1: Priority | E1: Preconditions | F1: Test Steps | G1: Test Data | H1: Expected Result | I1: Type | J1: Status | K1: Actual Result | L1: Tester | M1: Date | N1: Defect / Notes
A2: EXP-001 | B2: Explore | C2: Marketplace gated 'Coming Soon' when flag off | D2: P1 | E2: _marketplaceEnabled=false | F2: 1. Open Explore | G2: - | H2: 'Coming Soon' overlay shown regardless of data | I2: UI | J2: Not Run
A3: EXP-002 | B3: Explore | C3: Listings grid when enabled | D3: P2 | E3: Flag on, listings exist | F3: 1. Open Explore | G3: is_listed_in_marketplace=true | H3: Grid of marketplace projects; sorted by marketplace_sort_order | I3: UI | J3: Not Run
A4: EXP-003 | B4: Explore | C4: Filters (Open / Coming Soon) + empty + error | D4: P2 | E4: Flag on | F4: 1. Toggle filters | G4: - | H4: Filtered correctly; empty-state per filter; Retry card on error | I4: UI | J4: Not Run
A5: EXP-004 | B5: Explore | C5: Explore detail screen | D5: P2 | E5: A listing | F5: 1. Open a listing | G5: - | H5: Detail renders; CTA behaves | I5: UI | J5: Not Run
A6: EXIT-001 | B6: Exit | C6: Eligibility screen renders | D6: P0 | E6: Investor with units | F6: 1. Open Exit | G6: - | H6: Lock-in, earliest unit, eligibility grid shown; placeholders ('—') when data absent, not broken | I6: UI | J6: Not Run
A7: EXIT-002 | B7: Exit | C7: Pending exit request shown | D7: P1 | E7: Pending exit exists | F7: 1. Open Exit | G7: exit_requests row | H7: Pending state surfaced clearly | I7: UI | J7: Not Run
A8: EXIT-003 | B8: Exit | C8: Exit error fallback | D8: P1 | E8: Force failure | F8: 1. Open offline | G8: - | H8: Eligibility shows neutral placeholders; no raw error/crash | I8: UI | J8: Not Run
A9: EXIT-004 | B9: Exit | C9: Exit-settled notification | D9: P2 | E9: Exit settled in backend | F9: 1. Settle exit 2. Check Activity | G9: - | H9: 'Exit settled' notification delivered | I9: E2E | J9: Not Run

Sheet Profile & Settings
A1: Test ID | B1: Area | C1: Scenario | D1: Priority | E1: Preconditions | F1: Test Steps | G1: Test Data | H1: Expected Result | I1: Type | J1: Status | K1: Actual Result | L1: Tester | M1: Date | N1: Defect / Notes
A2: PROF-001 | B2: Profile | C2: Profile header shows name/email | D2: P0 | E2: Logged in | F2: 1. Open Profile | G2: - | H2: Real name/email; sensible fallback while loading (no flash of wrong name) | I2: UI | J2: Not Run
A3: PROF-002 | B3: Profile | C3: KYC screen status + resubmission | D3: P1 | E3: Investor KYC record | F3: 1. Open KYC | G3: - | H3: Status correct; resubmission flow works; notification on resubmit | I3: E2E | J3: Not Run
A4: PROF-003 | B4: Profile | C4: Bank details view + change request | D4: P0 | E4: Logged in | F4: 1. Open Bank details 2. Submit change | G4: New bank info | H4: bank-change-request edge fn called (NOT direct DB write); confirmation + notify-bank-update | I4: E2E | J4: Not Run
A5: PROF-004 | B5: Profile | C5: Bank/KYC screens have error state | D5: P1 | E5: Force failure | F5: 1. Open offline | G5: - | H5: Friendly error state (not blank/crash) | I5: UI | J5: Not Run
A6: SET-001 | B6: Settings | C6: Security screen: app lock + biometric toggles | D6: P1 | E6: Logged in | F6: 1. Toggle app lock / biometric | G6: - | H6: Settings persist (user_settings); reflected on next launch | I6: UI | J6: Not Run
A7: SET-002 | B7: Settings | C7: Login history (login_events) | D7: P2 | E7: Prior logins | F7: 1. Open security → history | G7: - | H7: Recent logins listed; inner error shows graceful state | I7: UI | J7: Not Run
A8: SET-003 | B8: Settings | C8: Notification preferences | D8: P2 | E8: Logged in | F8: 1. Change prefs | G8: - | H8: Saved to user_settings; respected by app | I8: Backend | J8: Not Run

Sheet Support
A1: Test ID | B1: Area | C1: Scenario | D1: Priority | E1: Preconditions | F1: Test Steps | G1: Test Data | H1: Expected Result | I1: Type | J1: Status | K1: Actual Result | L1: Tester | M1: Date | N1: Defect / Notes
A2: SUP-001 | B2: Support | C2: Support screen WhatsApp CTA | D2: P2 | E2: Logged in | F2: 1. Open Support 2. Tap WhatsApp | G2: - | H2: Opens WhatsApp with prefilled context; graceful if app absent | I2: UI | J2: Not Run
A3: SUP-002 | B3: Support | C3: Create ticket | D3: P1 | E3: Logged in | F3: 1. New ticket 2. Submit | G3: Subject+body | H3: create-ticket edge fn (JWT) creates ticket; appears in list; first-message notification | I3: E2E | J3: Not Run
A4: SUP-003 | B4: Support | C4: Reply to ticket | D4: P1 | E4: Open ticket | F4: 1. Open ticket 2. Reply | G4: Message | H4: reply-ticket edge fn adds message; thread updates | I4: E2E | J4: Not Run
A5: SUP-004 | B5: Support | C5: Ticket detail thread renders | D5: P2 | E5: Ticket w/ messages | F5: 1. Open ticket | G5: - | H5: Messages in order; statuses correct | I5: UI | J5: Not Run
A6: SUP-005 | B6: Support | C6: Consultation request | D6: P2 | E6: - | F6: 1. Submit consultation request | G6: - | H6: notify-consultation-request fires (Slack/email); confirmation to user | I6: E2E | J6: Not Run

Sheet Cross-Cutting (UX-Perf-Sec)
A1: Test ID | B1: Area | C1: Scenario | D1: Priority | E1: Preconditions | F1: Test Steps | G1: Test Data | H1: Expected Result | I1: Type | J1: Status | K1: Actual Result | L1: Tester | M1: Date | N1: Defect / Notes
A2: XC-001 | B2: Resilience | C2: Global error boundary catches widget crash | D2: P0 | E2: - | F2: 1. Force a widget build exception | G2: - | H2: Branded 'Something went wrong / Try again' card shown (NOT red Flutter error screen); Sentry captures it | I2: UI | J2: Not Run
A3: XC-002 | B3: Offline | C3: Hive cache serves data offline | D3: P0 | E3: Data loaded, then offline | F3: 1. Go offline 2. Browse | G3: - | H3: Last-known data renders across tabs; no crashes; sync badge reflects state | I3: UI | J3: Not Run
A4: XC-003 | B4: Navigation | C4: GoRouter back / bottom-nav behavior | D4: P1 | E4: - | F4: 1. Navigate deep then back | G4: - | H4: Back returns expected screen; bottom-nav roots don't stack incorrectly | I4: UI | J4: Not Run
A5: XC-004 | B5: Data isolation | C5: Demo vs real data never mix | D5: P0 | E5: Sign in from demo browse | F5: 1. Transition demo→auth | G5: - | H5: No residual demo rows after auth; no real data leaks in demo mode | I5: Security | J5: Not Run
A6: XC-005 | B6: Security | C6: Doc viewer screenshot prevention | D6: P1 | E6: Open a document | F6: 1. Attempt screenshot / screen record | G6: - | H6: Android FLAG_SECURE blocks; iOS blurs during capture/background | I6: Security | J6: Not Run
A7: XC-006 | B7: Gating | C7: Force-update screen below min version | D7: P0 | E7: App version < min | F7: 1. Launch | G7: latest-app-version min | H7: Force-update gate shown; app blocked until updated | I7: UI | J7: Not Run
A8: XC-007 | B8: Gating | C8: Maintenance screen when enabled | D8: P1 | E8: Maintenance flag on | F8: 1. Launch | G8: - | H8: Maintenance screen shown; recovers when flag cleared | I8: UI | J8: Not Run
A9: XC-008 | B9: Performance | C9: Read-heavy lists scroll smoothly | D9: P1 | E9: Large projects/payouts/docs lists | F9: 1. Fast-scroll | G9: Many rows | H9: No jank/ANR; images lazy-load; memory stable | I9: Performance | J9: Not Run
A10: XC-009 | B10: Accessibility | C10: Font scaling & contrast | D10: P2 | E10: OS large font | F10: 1. Increase system font | G10: - | H10: Layouts adapt without clipping; brand colors meet contrast | I10: Accessibility | J10: Not Run
A11: XC-010 | B11: Formatting | C11: INR currency & dates consistent | D11: P2 | E11: - | F11: 1. Inspect amounts/dates app-wide | G11: - | H11: Consistent ₹ formatting and date formats; no locale glitches | I11: UI | J11: Not Run
A12: XC-011 | B12: Web parity | C12: Responsive web build | D12: P2 | E12: Web target | F12: 1. Open on desktop browser | G12: - | H12: Layout responsive; mouse/trackpad scroll works; parity with mobile design | I12: UI | J12: Not Run
A13: XC-012 | B13: Observability | C13: Sentry captures errors without PII | D13: P1 | E13: Sentry configured | F13: 1. Trigger handled error | G13: - | H13: Error reported; PII scrubbed (PAN/Aadhaar/email redacted) | I13: Security | J13: Not Run

Sheet Backend - DB & RLS
A1: Test ID | B1: Area | C1: Scenario | D1: Priority | E1: Preconditions | F1: Test Steps | G1: Test Data | H1: Expected Result | I1: Type | J1: Status | K1: Actual Result | L1: Tester | M1: Date | N1: Defect / Notes
A2: BE-DB-001 | B2: RLS | C2: documents tiered read: common | D2: P0 | E2: Any authenticated user | F2: 1. SELECT from documents as user | G2: visibility=common | H2: Common rows returned to all authenticated users | I2: RLS | J2: Not Run
A3: BE-DB-002 | B3: RLS | C3: documents tiered read: project | D3: P0 | E3: User with/without allocation | F3: 1. SELECT project-tier rows | G3: visibility=project | H3: Only users with non-zero units in project_id can read | I3: RLS | J3: Not Run
A4: BE-DB-003 | B4: RLS | C4: documents tiered read: investor | D4: P0 | E4: Owner vs other | F4: 1. SELECT investor-tier rows | G4: visibility=investor | H4: Only investor_id = auth.uid() can read | I4: RLS | J4: Not Run
A5: BE-DB-004 | B5: RLS | C5: project_documents read policy | D5: P0 | E5: is_public / allocation | F5: 1. SELECT project_documents | G5: - | H5: is_public=true OR investor has non-zero, non-deleted units | I5: RLS | J5: Not Run
A6: BE-DB-005 | B6: Security | C6: projects_public view omits coordinates | D6: P0 | E6: - | F6: 1. SELECT from projects_public | G6: - | H6: No latitude/longitude columns exposed (S-002) | I6: Security | J6: Not Run
A7: BE-DB-006 | B7: RLS | C7: investor_units scoped to owner | D7: P0 | E7: Two investors | F7: 1. SELECT investor_units | G7: - | H7: Each sees only own rows | I7: RLS | J7: Not Run
A8: BE-DB-007 | B8: Backend | C8: portfolio_summary excludes demo + security invoker | D8: P1 | E8: - | F8: 1. Query view | G8: - | H8: Demo rows excluded; view runs as invoker (no privilege escalation) | I8: Backend | J8: Not Run
A9: BE-DB-008 | B9: RLS | C9: Soft-deleted rows excluded | D9: P1 | E9: deleted_at set | F9: 1. SELECT affected tables | G9: - | H9: deleted_at IS NOT NULL rows hidden from investor reads | I9: RLS | J9: Not Run
A10: BE-DB-009 | B10: Security | C10: Client cannot write protected tables | D10: P0 | E10: Authenticated client | F10: 1. Attempt INSERT/UPDATE via client | G10: - | H10: Denied; writes only via edge functions (service role) | I10: Security | J10: Not Run
A11: BE-DB-010 | B11: Backend | C11: webhook_log allows 'documents_sync' source | D11: P1 | E11: - | F11: 1. INSERT source='documents_sync' | G11: - | H11: Accepted (constraint updated in 057); sync runs are logged | I11: Backend | J11: Not Run
A12: BE-DB-011 | B12: Backend | C12: documents.storage_path prefix CHECK | D12: P1 | E12: - | F12: 1. INSERT path 'documents/...' | G12: - | H12: Rejected; must be common/ project/<uuid>/ investor/<uuid>/ | I12: Backend | J12: Not Run
A13: BE-DB-012 | B13: Backend | C13: investors.zoho_contact_id unique | D13: P1 | E13: - | F13: 1. Insert duplicate zoho_contact_id | G13: - | H13: Unique violation; no duplicate investor mapping | I13: Backend | J13: Not Run
A14: BE-DB-013 | B14: Security | C14: Anonymous cannot read protected data | D14: P0 | E14: No JWT | F14: 1. Query as anon | G14: - | H14: RLS denies; only intended public/demo paths accessible | I14: Security | J14: Not Run

Sheet Backend - Edge Functions & Sync
A1: Test ID | B1: Area | C1: Scenario | D1: Priority | E1: Preconditions | F1: Test Steps | G1: Test Data | H1: Expected Result | I1: Type | J1: Status | K1: Actual Result | L1: Tester | M1: Date | N1: Defect / Notes
A2: BE-FN-001 | B2: Backend | C2: documents-sync rejects without shared secret | D2: P0 | E2: Function deployed | F2: 1. POST without x-arl-cron-secret | G2: - | H2: 401 unauthorized | I2: Security | J2: Not Run
A3: BE-FN-002 | B3: Backend | C3: documents-sync project docs path | D3: P0 | E3: Zoho LLP w/ PDF attachment | F3: 1. Invoke with secret | G3: LLP_Creation_Module attachment | H3: File uploaded to project/<id>/; row upserted in project_documents; notification sent | I3: E2E | J3: Not Run
A4: BE-FN-003 | B4: Backend | C4: documents-sync personal docs path | D4: P0 | E4: Contact w/ attachment + zoho_contact_id | F4: 1. Invoke | G4: Contacts attachment | H4: File to investor/<id>/; row in documents (visibility=investor); owner notified | I4: E2E | J4: Not Run
A5: BE-FN-004 | B5: Backend | C5: documents-sync idempotency | D5: P0 | E5: Already-synced files | F5: 1. Invoke twice | G5: - | H5: No duplicate rows/objects (zoho_file_id de-dupe); webhook_log shows 0 new on 2nd run | I5: Backend | J5: Not Run
A6: BE-FN-005 | B6: Backend | C6: documents-sync logs to webhook_log | D6: P1 | E6: - | F6: 1. Invoke | G6: - | H6: Row source=documents_sync, status=processed, payload has scanned/new counts | I6: Backend | J6: Not Run
A7: BE-FN-006 | B7: Backend | C7: documents-sync daily cron fires | D7: P1 | E7: Cron scheduled | F7: 1. Wait for 06:15 IST run | G7: - | H7: cron.job 'documents-sync-daily' triggers function; webhook_log entry created | I7: Backend | J7: Not Run
A8: BE-FN-007 | B8: Backend | C8: gallery-sync llp_status fix (REGRESSION) | D8: P0 | E8: gallery-sync | F8: 1. Invoke gallery-sync | G8: - | H8: No 'projects.llp_status does not exist' error; images sync (apply same fix as documents-sync) | I8: Backend | J8: Not Run
A9: BE-FN-008 | B9: Backend | C9: zoho-crm-webhook upserts Contacts/LLP/Allocation | D9: P0 | E9: Zoho workflow | F9: 1. Send webhook payloads | G9: - | H9: investors/projects/llps/investor_units upserted; idempotent on (module,id,modified_time) | I9: E2E | J9: Not Run
A10: BE-FN-009 | B10: Backend | C10: zoho-crm-webhook delete cascade | D10: P1 | E10: Delete in Zoho | F10: 1. Send delete event | G10: - | H10: Cascades per spec (investors→dependents; SET NULL where defined) | I10: Backend | J10: Not Run
A11: BE-FN-010 | B11: Backend | C11: onboard-investor | D11: P1 | E11: New investor | F11: 1. Trigger onboarding | G11: - | H11: Investor provisioned correctly; no duplicates | I11: E2E | J11: Not Run
A12: BE-FN-011 | B12: Backend | C12: create-ticket / reply-ticket require JWT | D12: P0 | E12: - | F12: 1. Call without auth | G12: - | H12: Rejected; with valid JWT works | I12: Security | J12: Not Run
A13: BE-FN-012 | B13: Backend | C13: bank-change-request flow | D13: P1 | E13: - | F13: 1. Submit change | G13: - | H13: Request recorded; notify-bank-update fires; no direct client write to bank fields | I13: E2E | J13: Not Run
... A17: BE-FN-016 | B17: Backend | C17: Signed URL generation (documents/gallery) | D17: P1 | E17: Private buckets | F17: 1. Request signed URLs | G17: - | H17: Valid short-lived URLs for existing objects; empty/handled for missing | I17: Backend | J17: Not Run
