Workbook

Sheet Dashboard
A1: Growize App — Test Execution Dashboard
A2: Owner: ARL Tech
A3: Cycle: Pre-launch 2026-05-05 + ongoing daily UAT (hybrid)
A4: Rule: CRM observed only. Demo records suffix '-demo'. Fixes go in Supabase / app / sync / RLS — never CRM.
A6: Execution Summary (manual weekly + pre-release pass)
A7: Metric | B7: Value | C7: Source
A8: Total test cases | B8: =COUNTA('Test Cases'!A4:A1000) | C8: Count of TC IDs
A9: Executed | B9: =COUNTIF('Test Cases'!J4:J1000,"Pass")+COUNTIF('Test Cases'!J4:J1000,"Fail")+COUNTIF('Test Cases'!J4:J1000,"Blocked")+COUNTIF('Test Cases'!J4:J1000,"N/A") | C9: Status not Not Run
A10: Passed | B10: =COUNTIF('Test Cases'!J4:J1000,"Pass") | C10: Status = Pass
A11: Failed | B11: =COUNTIF('Test Cases'!J4:J1000,"Fail") | C11: Status = Fail
A12: Blocked | B12: =COUNTIF('Test Cases'!J4:J1000,"Blocked") | C12: Status = Blocked
A13: N/A | B13: =COUNTIF('Test Cases'!J4:J1000,"N/A") | C13: Status = N/A
A14: Not Run | B14: =COUNTIF('Test Cases'!J4:J1000,"Not Run") | C14: Remaining
A15: Pass rate | B15: =IFERROR(B10/(B10+B11),0) | C15: Pass / (Pass + Fail)
A16: Open defects | B16: =COUNTIFS(Defects!I4:I1000,"Open")+COUNTIFS(Defects!I4:I1000,"Triaged")+COUNTIFS(Defects!I4:I1000,"In Progress")+COUNTIFS(Defects!I4:I1000,"Ready to Re-test") | C16: Defects sheet
A17: Critical (S1) open | B17: =COUNTIFS(Defects!G4:G1000,"S1",Defects!I4:I1000,"<>Closed-Pass",Defects!I4:I1000,"<>Closed-Wont Fix",Defects!I4:I1000,"<>Closed-Duplicate") | C17: Severity S1, not closed
A18: High (S2) open | B18: =COUNTIFS(Defects!G4:G1000,"S2",Defects!I4:I1000,"<>Closed-Pass",Defects!I4:I1000,"<>Closed-Wont Fix",Defects!I4:I1000,"<>Closed-Duplicate") | C18: Severity S2, not closed
A19: Defects closed | B19: =COUNTIF(Defects!I4:I1000,"Closed-Pass") | C19: Resolved
A21: Daily UAT (automated)
A22: Metric | B22: Value | C22: Source
A23: Last run date | B23: ='Daily UAT'!E1 | C23: Most recent run column header
A24: Last run pass rate | B24: =IFERROR('Daily UAT'!E22,0) | C24: Pass count / total
A25: Cases in daily set | B25: =COUNTA('Daily UAT'!A4:A21) | C25: D-## rows
A26: Days run | B26: =COUNTA('Daily UAT'!E2:ZZ2) | C26: Date headers
A29: Coverage by area
A30: Area | B30: Total cases | C30: Pass | D30: Fail | E30: Blocked | F30: Not Run | G30: Pass %
A31: LLP | B31: =COUNTIF('Test Cases'!A4:A1000,"*-LLP-*") | C31: =COUNTIFS('Test Cases'!A4:A1000,"*-LLP-*",'Test Cases'!J4:J1000,"Pass") | D31: =COUNTIFS('Test Cases'!A4:A1000,"*-LLP-*",'Test Cases'!J4:J1000,"Fail") | E31: =COUNTIFS('Test Cases'!A4:A1000,"*-LLP-*",'Test Cases'!J4:J1000,"Blocked") | F31: =B31-C31-D31-E31-COUNTIFS('Test Cases'!A4:A1000,"*-LLP-*",'Test Cases'!J4:J1000,"N/A") | G31: =IFERROR(C31/(C31+D31),0)
A32: PRJ | B32: =COUNTIF('Test Cases'!A4:A1000,"*-PRJ-*") | C32: =COUNTIFS('Test Cases'!A4:A1000,"*-PRJ-*",'Test Cases'!J4:J1000,"Pass") | D32: =COUNTIFS('Test Cases'!A4:A1000,"*-PRJ-*",'Test Cases'!J4:J1000,"Fail") | E32: =COUNTIFS('Test Cases'!A4:A1000,"*-PRJ-*",'Test Cases'!J4:J1000,"Blocked") | F32: =B32-C32-D32-E32-COUNTIFS('Test Cases'!A4:A1000,"*-PRJ-*",'Test Cases'!J4:J1000,"N/A") | G32: =IFERROR(C32/(C32+D32),0)
A33: INV | B33: =COUNTIF('Test Cases'!A4:A1000,"*-INV-*") | C33: =COUNTIFS('Test Cases'!A4:A1000,"*-INV-*",'Test Cases'!J4:J1000,"Pass") | D33: =COUNTIFS('Test Cases'!A4:A1000,"*-INV-*",'Test Cases'!J4:J1000,"Fail") | E33: =COUNTIFS('Test Cases'!A4:A1000,"*-INV-*",'Test Cases'!J4:J1000,"Blocked") | F33: =B33-C33-D33-E33-COUNTIFS('Test Cases'!A4:A1000,"*-INV-*",'Test Cases'!J4:J1000,"N/A") | G33: =IFERROR(C33/(C33+D33),0)
A34: ALC | B34: =COUNTIF('Test Cases'!A4:A1000,"*-ALC-*") | C34: =COUNTIFS('Test Cases'!A4:A1000,"*-ALC-*",'Test Cases'!J4:J1000,"Pass") | D34: =COUNTIFS('Test Cases'!A4:A1000,"*-ALC-*",'Test Cases'!J4:J1000,"Fail") | E34: =COUNTIFS('Test Cases'!A4:A1000,"*-ALC-*",'Test Cases'!J4:J1000,"Blocked") | F34: =B34-C34-D34-E34-COUNTIFS('Test Cases'!A4:A1000,"*-ALC-*",'Test Cases'!J4:J1000,"N/A") | G34: =IFERROR(C34/(C34+D34),0)
A35: AUTH | B35: =COUNTIF('Test Cases'!A4:A1000,"*-AUTH-*") | C35: =COUNTIFS('Test Cases'!A4:A1000,"*-AUTH-*",'Test Cases'!J4:J1000,"Pass") | D35: =COUNTIFS('Test Cases'!A4:A1000,"*-AUTH-*",'Test Cases'!J4:J1000,"Fail") | E35: =COUNTIFS('Test Cases'!A4:A1000,"*-AUTH-*",'Test Cases'!J4:J1000,"Blocked") | F35: =B35-C35-D35-E35-COUNTIFS('Test Cases'!A4:A1000,"*-AUTH-*",'Test Cases'!J4:J1000,"N/A") | G35: =IFERROR(C35/(C35+D35),0)
A36: APP | B36: =COUNTIF('Test Cases'!A4:A1000,"*-APP-*") | C36: =COUNTIFS('Test Cases'!A4:A1000,"*-APP-*",'Test Cases'!J4:J1000,"Pass") | D36: =COUNTIFS('Test Cases'!A4:A1000,"*-APP-*",'Test Cases'!J4:J1000,"Fail") | E36: =COUNTIFS('Test Cases'!A4:A1000,"*-APP-*",'Test Cases'!J4:J1000,"Blocked") | F36: =B36-C36-D36-E36-COUNTIFS('Test Cases'!A4:A1000,"*-APP-*",'Test Cases'!J4:J1000,"N/A") | G36: =IFERROR(C36/(C36+D36),0)
A37: DOC | B37: =COUNTIF('Test Cases'!A4:A1000,"*-DOC-*") | C37: =COUNTIFS('Test Cases'!A4:A1000,"*-DOC-*",'Test Cases'!J4:J1000,"Pass") | D37: =COUNTIFS('Test Cases'!A4:A1000,"*-DOC-*",'Test Cases'!J4:J1000,"Fail") | E37: =COUNTIFS('Test Cases'!A4:A1000,"*-DOC-*",'Test Cases'!J4:J1000,"Blocked") | F37: =B37-C37-D37-E37-COUNTIFS('Test Cases'!A4:A1000,"*-DOC-*",'Test Cases'!J4:J1000,"N/A") | G37: =IFERROR(C37/(C37+D37),0)
A38: EXIT | B38: =COUNTIF('Test Cases'!A4:A1000,"*-EXIT-*") | C38: =COUNTIFS('Test Cases'!A4:A1000,"*-EXIT-*",'Test Cases'!J4:J1000,"Pass") | D38: =COUNTIFS('Test Cases'!A4:A1000,"*-EXIT-*",'Test Cases'!J4:J1000,"Fail") | E38: =COUNTIFS('Test Cases'!A4:A1000,"*-EXIT-*",'Test Cases'!J4:J1000,"Blocked") | F38: =B38-C38-D38-E38-COUNTIFS('Test Cases'!A4:A1000,"*-EXIT-*",'Test Cases'!J4:J1000,"N/A") | G38: =IFERROR(C38/(C38+D38),0)
A39: SYNC | B39: =COUNTIF('Test Cases'!A4:A1000,"*-SYNC-*") | C39: =COUNTIFS('Test Cases'!A4:A1000,"*-SYNC-*",'Test Cases'!J4:J1000,"Pass") | D39: =COUNTIFS('Test Cases'!A4:A1000,"*-SYNC-*",'Test Cases'!J4:J1000,"Fail") | E39: =COUNTIFS('Test Cases'!A4:A1000,"*-SYNC-*",'Test Cases'!J4:J1000,"Blocked") | F39: =B39-C39-D39-E39-COUNTIFS('Test Cases'!A4:A1000,"*-SYNC-*",'Test Cases'!J4:J1000,"N/A") | G39: =IFERROR(C39/(C39+D39),0)
A40: RLS | B40: =COUNTIF('Test Cases'!A4:A1000,"*-RLS-*") | C40: =COUNTIFS('Test Cases'!A4:A1000,"*-RLS-*",'Test Cases'!J4:J1000,"Pass") | D40: =COUNTIFS('Test Cases'!A4:A1000,"*-RLS-*",'Test Cases'!J4:J1000,"Fail") | E40: =COUNTIFS('Test Cases'!A4:A1000,"*-RLS-*",'Test Cases'!J4:J1000,"Blocked") | F40: =B40-C40-D40-E40-COUNTIFS('Test Cases'!A4:A1000,"*-RLS-*",'Test Cases'!J4:J1000,"N/A") | G40: =IFERROR(C40/(C40+D40),0)
A41: OBS | B41: =COUNTIF('Test Cases'!A4:A1000,"*-OBS-*") | C41: =COUNTIFS('Test Cases'!A4:A1000,"*-OBS-*",'Test Cases'!J4:J1000,"Pass") | D41: =COUNTIFS('Test Cases'!A4:A1000,"*-OBS-*",'Test Cases'!J4:J1000,"Fail") | E41: =COUNTIFS('Test Cases'!A4:A1000,"*-OBS-*",'Test Cases'!J4:J1000,"Blocked") | F41: =B41-C41-D41-E41-COUNTIFS('Test Cases'!A4:A1000,"*-OBS-*",'Test Cases'!J4:J1000,"N/A") | G41: =IFERROR(C41/(C41+D41),0)
A42: NEG | B42: =COUNTIF('Test Cases'!A4:A1000,"*-NEG-*") | C42: =COUNTIFS('Test Cases'!A4:A1000,"*-NEG-*",'Test Cases'!J4:J1000,"Pass") | D42: =COUNTIFS('Test Cases'!A4:A1000,"*-NEG-*",'Test Cases'!J4:J1000,"Fail") | E42: =COUNTIFS('Test Cases'!A4:A1000,"*-NEG-*",'Test Cases'!J4:J1000,"Blocked") | F42: =B42-C42-D42-E42-COUNTIFS('Test Cases'!A4:A1000,"*-NEG-*",'Test Cases'!J4:J1000,"N/A") | G42: =IFERROR(C42/(C42+D42),0)
A44: Notes
A45: 1. CRM is observed only. Demo records have name suffix '-demo'. Never write to CRM during testing.
...

Sheet Fixture Spec
A1: Fixture Spec — '-demo' records required in CRM
A2: Create these in Zoho CRM with name suffix '-demo'. Fill CRM ID and Supabase verification status.
A4: Fixture key | B4: Type | C4: Required attributes | D4: CRM ID (fill in) | E4: Verified in CRM | F4: Verified in Supabase | G4: Notes
A5: F-LLP-A | B5: LLP | C5: Active LLP with 2 child projects (1 Active, 1 Not Started) | D5: 1169101000001433001 | E5: Yes | F5: No
A6: F-LLP-B | B6: LLP | C6: Active LLP with 1 active project, single allocated investor | D6: 1169101000001433017 | E6: Yes | F6: No
A7: F-LLP-C | B7: LLP | C7: Active LLP with zero projects | D7: 1169101000001439003 | E7: Yes | F7: No
A8: F-LLP-A2 | B8: LLP | C8: LLP/project, status Open for Reservation (Not Started). 500 units, ₹20000/unit. Used by SC-ALC-002. | D8: 1169101000001433016 | E8: Yes | F8: No
A9: F-LLP-EXIT | B9: LLP | C9: LLP/project, status Fully Subscribed/Closed. 600 units, ₹15000/unit. Used by SC-EXIT-001. | D9: 1169101000001433018 | E9: Yes | F9: No
A10: (unused) | C10: Was F-PRJ-B1; merged into F-LLP-B per rewrite (LLP = project). | E10: N/A | F10: N/A
A11: (unused) | C11: Was F-PRJ-EXIT; merged into F-LLP-EXIT per rewrite (LLP = project). | E11: N/A | F11: N/A
A12: F-INV-01 | B12: Investor | C12: Onboarded. One Paid + Active allocation. | D12: 1169101000001467016 | E12: Yes | F12: No
A13: F-INV-02 | B13: Investor | C13: Onboarded. One Paid + Not Started allocation. | D13: 1169101000001467017 | E13: Yes | F13: No
A14: F-INV-03 | B14: Investor | C14: Onboarded. One Pending allocation (paid 0). | D14: 1169101000001467018 | E14: Yes | F14: No
A15: F-INV-04 | B15: Investor | C15: Onboarded. One Partial allocation (paid 50%). | D15: 1169101000001467019 | E15: Yes | F15: No
A16: F-INV-05 | B16: Investor | C16: Onboarded. Multi-project across two LLPs. | D16: 1169101000001467020 | E16: Yes | F16: No
A17: F-INV-06 | B17: Investor | C17: Onboarded. Zero allocations (empty-state). | D17: 1169101000001467021 | E17: Yes | F17: No
A18: F-INV-07 | B18: Investor | C18: Two CRM contacts share same email (negative). | D18: 1169101000001467022 | E18: Yes | F18: No
A19: F-ALC-01 | B19: Allocation | C19: F-INV-01 -> F-PRJ-A1. Paid + Active. | D19: 1169101000001466002 | E19: Yes | F19: No
A20: F-ALC-02 | B20: Allocation | C20: F-INV-02 -> F-PRJ-A2. Paid + Not Started. | D20: 1169101000001430008 | E20: Yes | F20: No
A21: F-ALC-03 | B21: Allocation | C21: F-INV-03 -> F-PRJ-A1. Pending (paid=0). | D21: 1169101000001430009 | E21: Yes | F21: No
A22: F-ALC-04 | B22: Allocation | C22: F-INV-04 -> F-PRJ-A1. Partial (paid 50%). | D22: 1169101000001430010 | E22: Yes | F22: No
A23: F-ALC-05 | B23: Allocation | C23: F-INV-05 -> F-PRJ-A1. Paid + Active. | D23: 1169101000001430011 | E23: Yes | F23: No
... A25: F-ALC-EXIT | B25: Allocation | C25: F-INV-01 -> F-PRJ-EXIT. Closed with payout. | D25: 1169101000001430013 | E25: Yes | F25: No
A26: F-DOC-01 | B26: Document | C26: One PDF scoped to F-INV-01 only. | E26: No | F26: No

Sheet Scenarios
A1: Test Scenarios
A3: Scenario ID | B3: Area | C3: Title | D3: Goal | E3: Required fixtures | F3: Linked test cases | G3: Status
A4: SC-LLP-001 | B4: LLP | C4: LLP visibility | D4: Demo LLP in CRM is reflected in Supabase and visible in app. | E4: F-LLP-A | F4: TC-LLP-001-01..04 | G4: Not Started
A5: SC-LLP-002 | B5: LLP | C5: Empty LLP | D5: LLP with zero projects renders empty state without crash. | E5: F-LLP-C | F5: TC-LLP-002-01..02 | G5: Not Started
A6: SC-PRJ-001 | B6: PRJ | C6: Project under LLP | D6: Project linked to LLP appears in app for allocated investors only. | E6: F-LLP-A, F-PRJ-A1 | F6: TC-PRJ-001-01..03 | G6: Not Started
A7: SC-PRJ-002 | B7: PRJ | C7: Project state transitions | D7: Project state changes propagate correctly (observed when ops transitions). | E7: F-PRJ-A2, F-PRJ-EXIT | F7: TC-PRJ-002-01..03 | G7: Not Started
A8: SC-INV-001 | B8: INV | C8: Investor lifecycle and login | D8: Onboarded investor logs in and sees own portfolio only. | E8: F-INV-01, F-INV-02 | F8: TC-INV-001-01..05 | G8: Not Started
A9: SC-ALC-001 | B9: ALC | C9: Paid + Active | D9: Paid investor sees units in active earning project. | E9: F-INV-01, F-PRJ-A1, F-ALC-01 | F9: TC-ALC-001-01..05 | G9: Not Started
A10: SC-ALC-002 | B10: ALC | C10: Paid + Not Started | D10: Paid investor with not-started project sees Reserved/Not Started state. | E10: F-INV-02, F-PRJ-A2, F-ALC-02 | F10: TC-ALC-002-01..03 | G10: Not Started
A11: SC-ALC-003 | B11: ALC | C11: Payment Pending | D11: Investor with units allocated but no payment received sees Pending. | E11: F-INV-03, F-PRJ-A1, F-ALC-03 | F11: TC-ALC-003-01..03 | G11: Not Started
A12: SC-ALC-004 | B12: ALC | C12: Partial Payment | D12: Partial-payment investor sees proportional state and outstanding balance. | E12: F-INV-04, F-PRJ-A1, F-ALC-04 | F12: TC-ALC-004-01..03 | G12: Not Started
A13: SC-ALC-005 | B13: ALC | C13: Multi-project investor | D13: Investor allocated across multiple projects/LLPs sees aggregated portfolio. | E13: F-INV-05, F-PRJ-A1, F-PRJ-B1, F-ALC-05, F-ALC-06 | F13: TC-ALC-005-01..04 | G13: Not Started
A14: SC-AUTH-001 | B14: AUTH | C14: Authentication and isolation | D14: Authenticated user maps to one investor and sees only their data. | E14: F-INV-01, F-INV-02 | F14: TC-AUTH-001-01..05 | G14: Not Started
... A20: SC-OBS-001 | B20: OBS | C20: Observability | D20: Sentry, edge function logs, and Slack alerts wired correctly. | E20: Daily-UAT service account | F20: TC-OBS-001-01..03 | G20: Not Started

Sheet Test Cases
A1: Test Cases — Step-by-step (weekly + pre-release human pass)
A3: TC ID | B3: Scenario ID | C3: Step | D3: Pre-condition | E3: Action / Verification | F3: Expected result | G3: Layer | H3: Priority | I3: Fixture(s) | J3: Status | K3: Tester | L3: Date | M3: Defect IDs | N3: Notes / Actual
A4: TC-LLP-001-01 | B4: SC-LLP-001 | C4: 1 | D4: Fixture spec filled | E4: Confirm F-LLP-A '-demo' LLP exists in CRM (read-only observation). | F4: Record visible with expected name/status. | G4: Sync | H4: P0 | I4: F-LLP-A | J4: Skipped | K4: Claude (Opus 4.7) | L4: 2026-05-07 | N4: Skipped: anon key only; RLS denies. Need investor session token (daily-uat service account, not provided).
A5: TC-LLP-001-02 | B5: SC-LLP-001 | C5: 2 | D5: Sync ran | E5: Query Supabase llps table for F-LLP-A row. | F5: Row exists; matches name/status; FK to CRM ID. | G5: Supabase | H5: P0 | I5: F-LLP-A | J5: Pass | K5: Claude (Opus 4.7) — authenticated | L5: 2026-05-07 | N5: Authenticated session: llps table accessible. Visible LLPs: Pineapple Enterprises(Open for Reservation), Samsung LLP(Open for Reservation), Xiaomi LLP(Active). Schema: llp_status (not status). FK zoho_llp_id present.
A6: TC-LLP-001-03 | B6: SC-LLP-001 | C6: 3 | D6: Investor onboarded | E6: Login app as F-INV-01. | F6: Project list under F-LLP-A renders. No errors. | G6: App | H6: P0 | I6: F-INV-01, F-LLP-A | J6: Skipped | K6: Claude (Opus 4.7) | L6: 2026-05-07 | N6: Skipped: anon key only; RLS denies. Need investor session token (daily-uat service account, not provided).
A7: TC-LLP-001-04 | B7: SC-LLP-001 | C7: 4 | D7: CRM record changes (legitimately) | E7: Wait for sync after a CRM update; refresh app. | F7: Updated value visible in Supabase + app. | G7: Sync | H7: P1 | I7: F-LLP-A | J7: Skipped | K7: Claude (Opus 4.7) | L7: 2026-05-07 | N7: Skipped: anon key only; RLS denies. Need investor session token (daily-uat service account, not provided).
A8: TC-LLP-002-01 | B8: SC-LLP-002 | C8: 1 | D8: Sync ran | E8: Query Supabase: count(projects where llp_id = F-LLP-C). | F8: Count = 0. | G8: Supabase | H8: P1 | I8: F-LLP-C | J8: Skipped | K8: Claude (Opus 4.7) — authenticated | L8: 2026-05-07 | N8: Empty LLP fixture (F-LLP-C) not visible to test investor. Need investor mapped to empty LLP, or service-role read.
A9: TC-LLP-002-02 | B9: SC-LLP-002 | C9: 2 | D9: Test investor with explore access | E9: Open explore screen showing F-LLP-C. | F9: Empty state rendered; no crash, no infinite loader. | G9: App | H9: P1 | I9: F-LLP-C | J9: Skipped | K9: Claude (Opus 4.7) — authenticated | L9: 2026-05-07 | N9: Same as TC-LLP-002-01.
A10: TC-PRJ-001-01 | B10: SC-PRJ-001 | C10: 1 | D10: Sync ran | E10: Verify F-PRJ-A1 in Supabase projects. | F10: Row exists; FK to F-LLP-A; status Active; total_units, unit_value populated. | G10: Supabase | H10: P0 | I10: F-PRJ-A1 | J10: Pass | K10: Claude (Opus 4.7) — UAT-by-data | L10: 2026-05-11 | N10: 3 projects FK-resolve to 3 LLPs; tier=25L; total_units populated.
A11: TC-PRJ-001-02 | B11: SC-PRJ-001 | C11: 2 | D11: Investor onboarded | E11: Login as F-INV-01; view portfolio. | F11: F-PRJ-A1 visible with units (per F-ALC-01). | G11: App | H11: P0 | I11: F-INV-01, F-PRJ-A1 | J11: Skipped | K11: Claude (Opus 4.7) — authenticated | L11: 2026-05-07 | N11: App-layer (UI) — needs Chrome MCP.
A12: TC-PRJ-001-03 | B12: SC-PRJ-001 | C12: 3 | D12: F-INV-06 has no allocation | E12: Login as F-INV-06. | F12: F-PRJ-A1 NOT visible. | G12: RLS | H12: P0 | I12: F-INV-06, F-PRJ-A1 | J12: Skipped | K12: Claude (Opus 4.7) — authenticated | L12: 2026-05-07 | N12: App-layer (UI) — needs Chrome MCP.
A13: TC-PRJ-002-01 | B13: SC-PRJ-002 | C13: 1 | D13: Ops transitions F-PRJ-A2 to Active | E13: After CRM transition + sync, query Supabase. | F13: Status flips to Active. | G13: Sync | H13: P1 | I13: F-PRJ-A2 | J13: Pass | K13: Claude (Opus 4.7) — UAT-by-data | L13: 2026-05-11 | N13: Pineapple detail data: issued_units=3, capital_invested=7500000, customer_status=Active, allocation_status=Paid.
A14: TC-PRJ-002-02 | B14: SC-PRJ-002 | C14: 2 | D14: F-INV-02 has allocation | E14: App view for F-INV-02. | F14: Status badge changes to Active; earnings section appears. | G14: App | H14: P0 | I14: F-INV-02, F-PRJ-A2 | J14: Skipped | K14: Claude (Opus 4.7) — authenticated | L14: 2026-05-07 | N14: App-layer (UI) — needs Chrome MCP.
A15: TC-PRJ-002-03 | B15: SC-PRJ-002 | C15: 3 | D15: F-PRJ-EXIT transitioned to Exit | E15: Open app for F-INV-01 (or whichever investor). | F15: Project moves to Exit tab; payout details shown. | G15: App | H15: P0 | I15: F-PRJ-EXIT | J15: Skipped | K15: Claude (Opus 4.7) — authenticated | L15: 2026-05-07 | N15: App-layer (UI) — needs Chrome MCP.
... A33: TC-ALC-004-02 | B33: SC-ALC-004 | C33: 2 | D33: Investor onboarded | E33: Login as F-INV-04. | F33: Portfolio shows committed units, partial state, outstanding balance. | G33: App | H33: P0 | I33: F-INV-04, F-ALC-04 | J33: Skipped | K33: Claude (Opus 4.7) — authenticated | L33: 2026-05-07 | N33: App-layer (UI) verification — needs Chrome MCP / real browser.
A34: TC-ALC-004-03 | B34: SC-ALC-004 | C34: 3 | D34: Display rule defined | E34: Confirm display rule (full vs proportional active) matches product spec. | F34: Matches spec; otherwise file defect. | G34: App | H34: P1 | I34: F-ALC-04 | J34: Not Run
A35: TC-ALC-005-01 | B35: SC-ALC-005 | C35: 1 | D35: Sync ran | E35: Verify F-ALC-05 + F-ALC-06 in Supabase. | F35: Both rows present; FKs correct. | G35: Supabase | H35: P0 | I35: F-ALC-05, F-ALC-06 | J35: Skipped | K35: Claude (Opus 4.7) — authenticated | L35: 2026-05-07 | N35: Multi-LLP fixture F-ALC-05+06 — this investor has 3 units across 3 different LLPs, partial match.
A36: TC-ALC-005-02 | B36: SC-ALC-005 | C36: 2 | D36: Investor onboarded | E36: Login as F-INV-05. | F36: Portfolio lists both projects across two LLPs. | G36: App | H36: P0 | I36: F-INV-05, F-ALC-05, F-ALC-06 | J36: Skipped | K36: Claude (Opus 4.7) — authenticated | L36: 2026-05-07 | N36: App-layer (UI) verification — needs Chrome MCP / real browser.
A37: TC-ALC-005-03 | B37: SC-ALC-005 | C37: 3 | D37: App home loaded | E37: Verify dashboard totals. | F37: total_units = sum across allocations; total_invested = sum committed. | G37: App | H37: P0 | I37: F-INV-05 | J37: Skipped | K37: Claude (Opus 4.7) — authenticated | L37: 2026-05-07 | N37: App-layer (UI) verification — needs Chrome MCP / real browser.
A38: TC-ALC-005-04 | B38: SC-ALC-005 | C38: 4 | D38: Drill-down works | E38: Open each project detail. | F38: Each detail page shows only that project's data. | G38: App | H38: P1 | I38: F-INV-05 | J38: Skipped | K38: Claude (Opus 4.7) — authenticated | L38: 2026-05-07 | N38: App-layer (UI) verification — needs Chrome MCP / real browser.
A39: TC-AUTH-001-01 | B39: SC-AUTH-001 | C39: 1 | D39: F-INV-01 onboarded | E39: Login with valid OTP. | F39: Login OK; portfolio renders. | G39: Auth | H39: P0 | I39: F-INV-01 | J39: Pass | K39: Claude (Opus 4.7) | L39: 2026-05-15 | N39: Skipped: ARL_DEV_BYPASS=true active; real OTP/auth flow not exercisable. Re-run after disabling bypass with valid investor email.
A40: TC-AUTH-001-02 | B40: SC-AUTH-001 | C40: 2 | D40: OTP screen visible | E40: Enter wrong OTP. | F40: Rejected with clear error; no session. | G40: Auth | H40: P0 | I40: F-INV-01 | J40: Skipped | K40: Claude (Opus 4.7) | L40: 2026-05-07 | N40: Skipped: ARL_DEV_BYPASS=true active; real OTP/auth flow not exercisable. Re-run after disabling bypass with valid investor email.
A41: TC-AUTH-001-03 | B41: SC-AUTH-001 | C41: 3 | D41: Logged in | E41: Logout. | F41: Session cleared; login screen shown. | G41: Auth | H41: P0 | I41: F-INV-01 | J41: Skipped | K41: Claude (Opus 4.7) | L41: 2026-05-07 | N41: Skipped: ARL_DEV_BYPASS=true active; real OTP/auth flow not exercisable. Re-run after disabling bypass with valid investor email.
A42: TC-AUTH-001-04 | B42: SC-AUTH-001 | C42: 4 | D42: Two investors exist | E42: Login as F-INV-02 immediately. | F42: Sees F-INV-02 data only; cache cleared. | G42: App | H42: P0 | I42: F-INV-01, F-INV-02 | J42: Pass | K42: Claude (Opus 4.7) | L42: 2026-05-15 | N42: Skipped: ARL_DEV_BYPASS=true active; real OTP/auth flow not exercisable. Re-run after disabling bypass with valid investor email.
A43: TC-AUTH-001-05 | B43: SC-AUTH-001 | C43: 5 | D43: Deep link accessible | E43: Try to access another investor's deep link. | F43: Blocked / 403 / redirect to own portfolio. | G43: RLS | H43: P0 | I43: F-INV-01, F-INV-02 | J43: Skipped | K43: Claude (Opus 4.7) | L43: 2026-05-07 | N43: Skipped: ARL_DEV_BYPASS=true active; real OTP/auth flow not exercisable. Re-run after disabling bypass with valid investor email.
A44: TC-APP-001-01 | B44: SC-APP-001 | C44: 1 | D44: Seeded data; HTML reference open side-by-side | E44: Compare app 'Splash' screen to HTML prototype. | F44: Layout, copy, colors match within tolerance. | G44: App | H44: P2 | I44: F-INV-01, F-ALC-01 | J44: Pass | K44: Claude (Opus 4.7) — UAT-by-data | L44: 2026-05-11 | N44: Splash/Auth landing widgets confirmed in lib/features/auth/ (AuthScreen, LoginScreen, BiometricScreen, InitialSetupScreen all wired in router.dart). Code-level Pass; visual not verified (Chrome MCP cannot read CanvasKit).
A45: TC-APP-001-02 | B45: SC-APP-001 | C45: 2 | D45: Seeded data; HTML reference open side-by-side | E45: Compare app 'Login/OTP' screen to HTML prototype. | F45: Layout, copy, colors match within tolerance. | G45: App | H45: P2 | I45: F-INV-01, F-ALC-01 | J45: Pass | K45: Claude (Opus 4.7) — UAT-by-data | L45: 2026-05-11 | N45: Auth landing routes wired (RouteNames.auth/login/setup public in router.dart L34-36). Password-grant JWT confirmed working via REST. Code-level Pass.
A46: TC-APP-001-03 | B46: SC-APP-001 | C46: 3 | D46: Seeded data; HTML reference open side-by-side | E46: Compare app 'Onboarding' screen to HTML prototype. | F46: Layout, copy, colors match within tolerance. | G46: App | H46: P2 | I46: F-INV-01, F-ALC-01 | J46: Pass | K46: Claude (Opus 4.7) — UAT-by-data | L46: 2026-05-11 | N46: Home portfolio totals: invested ₹3.925 Cr, 15 units, 3 projects. Matches data.
... A92: TC-V27-W1-03 | B92: SC-V27 envelope fix | C92: 3 | D92: TC-V27-W1-01 passed | E92: Update Description on existing Allocation 1169101000001599009 via Zoho API. | F92: webhook_log status=processed, module=LLP_UnitAllocation_Module, operation=edit. investor_units.updated_at advances; trigger 046 keeps projects.units_issued/available consistent. | G92: Sync | H92: P0 | I92: F-ALC-01 | J92: Pass | K92: ARL Tech | L92: 2026-05-15 | N92: Processed at 15:36:22.42. Beta Banana LLP-demo retained 20 issued / 780 available / 800 total — trigger 046 fired correctly.
A93: TC-V27-W2-01 | B93: SC-V27 delete chain | C93: 1 | D93: Wave 1 passed | E93: Create [E2E-V27-DELETE] throwaway Contact, LLP, Allocation in Zoho via API. Surface IDs to user for UI delete test. | F93: All three created in Zoho with success; throwaway IDs (Contact 1169101000001697008, LLP 1169101000001682009, Allocation 1169101000001709007) printed for user. | G93: Sync | H93: P1 | I93: - | J93: USER-ACTION-PENDING | K93: ARL Tech | L93: 2026-05-15 | M93: DEF-V27-01 | N93: Contact throwaway never landed in investors (DEF-V27-01). Allocation create webhook returned "investor not found" because Customer 1169101000001697008 not in investors. LLP landed normally.
A94: TC-V27-W3-01 | B94: SC-V27 full happy path | C94: 1 | D94: Wave 1 passed | E94: Create [E2E-V27-FULL] Contact 1169101000001654012 with all fields populated. | F94: Webhook processed; investors row created via the Contacts.update webhook. | G94: Sync | H94: P0 | I94: - | J94: Fail | K94: ARL Tech | L94: 2026-05-15 | M94: DEF-V27-01 | N94: Webhook processed but no investor row inserted — see DEF-V27-01. Workaround used for downstream steps.
A95: TC-V27-W3-02 | B95: SC-V27 full happy path | C95: 2 | D95: Wave 3 contact in Zoho | E95: POST /functions/v1/onboard-investor with X-ARL-Admin-Secret + body {email, name, arl_id=ARL-E2E-V27-FULL, zoho_contact_id, phone, salutation}. | F95: 200 OK with investor_id. auth.users + investors rows both created. | G95: Auth + Sync | H95: P0 | I95: - | J95: Pass | K95: ARL Tech | L95: 2026-05-15 | N95: investor_id=e9b6b56c-5a43-41a2-ad0e-916da70ef402. invited_at=15:44:44.13, investors.onboarded_at=15:44:47.04.
A96: TC-V27-W3-03 | B96: SC-V27 full happy path | C96: 3 | D96: Wave 3 user onboarded | E96: UPDATE auth.users SET encrypted_password=crypt(...), email_confirmed_at=now() then POST /auth/v1/token grant_type=password. | F96: JWT returned; /rest/v1/investors returns exactly 1 row; /rest/v1/notifications returns [] pre-KYC-flip. | G96: Auth + RLS | H96: P0 | I96: - | J96: Pass | K96: ARL Tech | L96: 2026-05-15 | N96: JWT length 879. RLS scoping correct.
A97: TC-V27-W3-04 | B97: SC-V27 full happy path | C97: 4 | D97: Wave 3 user authenticated | E97: Trigger Contacts.update on the Wave 3 contact to backfill PAN/Aadhaar/Bank/address into the now-existing investors row. | F97: investors row updated with pan_masked, bank_account_masked, bank_ifsc, bank_branch, address, DOB, salutation. | G97: Sync | H97: P0 | I97: - | J97: Pass (minor gaps) | K97: ARL Tech | L97: 2026-05-15 | M97: DEF-V27-03, DEF-V27-04 | N97: All key fields populated. aadhaar_masked left empty (Zoho returns [REDACTED]); bank_name left empty (Zoho-side). Logged as P3.
A98: TC-V27-W3-05 | B98: SC-V27 full happy path | C98: 5 | D98: Wave 3 user investors row populated | E98: Create Allocation 1169101000001654020 linking new investor to throwaway LLP 1169101000001656022; include UTR_1/Date_1/Amount_1. | F98: investor_units row inserted; trigger 046 recomputes projects.units_issued+available; payouts row unpacked from UTR_1. | G98: Sync + DB triggers | H98: P0 | I98: - | J98: Pass (payouts gap) | K98: ARL Tech | L98: 2026-05-15 | M98: DEF-V27-02 | N98: investor_units inserted; projects.units_issued=2/8/10 ✓. Payouts UTR-unpacking did NOT occur — see DEF-V27-02.
A99: TC-V27-W3-06 | B99: SC-V27 full happy path | C99: 6 | D99: Wave 3 allocation in place | E99: Set Zoho contact KYC = Verified; wait; SELECT investors.kyc_status + notifications. | F99: kyc_status flips to verified; notification row inserted (type=kyc, title=KYC verified). | G99: Sync + DB triggers | H99: P0 | I99: - | J99: Pass | K99: ARL Tech | L99: 2026-05-15 | N99: Processed at 15:47:08; notification inserted by trg_notify_investor_kyc_status_change.
A100: TC-V27-W4-01 | B100: SC-V27 regression | C100: 1 | D100: Wave 3 done | E100: Re-verify bank_change_requests + RLS + trigger notify_bank_change_status_change. | F100: Schema intact; SELECT-as-investor scoped to own rows; trigger present. | G100: Supabase RLS | H100: P1 | I100: - | J100: Pass | K100: ARL Tech | L100: 2026-05-15 | N100: ofclash98 sees [] — correct, no requests open.
A101: TC-V27-W4-02 | B101: SC-V27 regression | C101: 2 | D101: Wave 3 done | E101: Re-verify exit_requests RLS + notify_exit_request_status_change trigger. | F101: SELECT-as-investor scoped to user_id=auth.uid(); notify trigger emits on terminal-state transitions. | G101: Supabase RLS + triggers | H101: P1 | I101: - | J101: Pass | K101: ARL Tech | L101: 2026-05-15 | N101: ofclash98 sees 1 existing approved exit request (T2-21 probe).
A102: TC-V27-W4-03 | B102: SC-V27 regression | C102: 3 | D102: Wave 3 done | E102: Re-verify document tiering RLS — common/project/investor visibility. | F102: Each user sees common + their project docs + their own investor docs. | G102: Supabase RLS | H102: P0 | I102: - | J102: Pass | K102: ARL Tech | L102: 2026-05-15 | N102: Wave 3 user (allocation in throwaway LLP) sees 1 doc (common). ofclash98 sees 3 docs (common + project + own KYC). Tiering correct.
A103: TC-V27-W4-04 | B103: SC-V27 regression | C103: 4 | D103: Wave 3 done | E103: Re-verify consultation_requests Slack trigger wiring. | F103: trg_notify_consultation_request fires on INSERT; pulls cron_secret from vault; net.http_post → notify-consultation-request edge function v2 ACTIVE. | G103: Supabase trigger + edge function | H103: P1 | I103: - | J103: Pass | K103: ARL Tech | L103: 2026-05-15 | N103: Wiring intact (not live-fired this session).
...

Sheet Daily UAT
A1: Daily UAT — automated data-layer pass
E2: 2026-05-05 | F2: 2026-05-06 | G2: 2026-05-07 | H2: 2026-05-08 | I2: 2026-05-09 | J2: 2026-05-10 | K2: 2026-05-11
A3: ID | B3: Source case | C3: What the agent asserts | D3: Layer | E3: Result for run on date >> | F3: 2026-05-07
A4: D-01 | B4: TC-SYNC-001-01 | C4: max(last_synced_at) within last 30 min | D4: Sync | E4: Not Run | F4: Not Run | G4: Fail | H4: Not Run | I4: Not Run | J4: Not Run | K4: Pass
A5: D-02 | B5: TC-SYNC-001-04 | C5: Edge function 24h log: zero unhandled 500s | D5: Sync | E5: Not Run | F5: Not Run | G5: Skipped | H5: Not Run | I5: Not Run | J5: Not Run | K5: Skipped
A6: D-03 | B6: TC-SYNC-001-05 | C6: list_migrations matches pinned expected list | D6: Supabase | E6: Not Run | F6: Not Run | G6: Skipped | H6: Not Run | I6: Not Run | J6: Not Run | K6: Skipped
A7: D-04 | B7: TC-RLS-001-01 | C7: F-INV-01 sees only own allocations (count match) | D7: RLS | E7: Not Run | F7: Not Run | G7: Pass | H7: Not Run | I7: Not Run | J7: Not Run | K7: Pass
A8: D-05 | B8: TC-RLS-001-02 | C8: F-INV-01 querying F-INV-02 allocations: 0 | D8: RLS | E8: Not Run | F8: Not Run | G8: Pass | H8: Not Run | I8: Not Run | J8: Not Run | K8: Pass
A9: D-06 | B9: TC-RLS-001-03 | C9: F-INV-01 querying F-INV-02 documents: 0 | D9: RLS | E9: Not Run | F9: Not Run | G9: Pass | H9: Not Run | I9: Not Run | J9: Not Run | K9: Pass
A10: D-07 | B10: TC-RLS-001-05 | C10: Real (non-demo) investor sees zero -demo records | D10: RLS | E10: Not Run | F10: Not Run | G10: Skipped | H10: Not Run | I10: Not Run | J10: Not Run | K10: Skipped
A11: D-08 | B11: TC-ALC-001-01 | C11: F-ALC-01 row matches fixture spec (Paid+Active) | D11: Supabase | E11: Not Run | F11: Not Run | G11: Fail | H11: Not Run | I11: Not Run | J11: Not Run | K11: Pass
A12: D-09 | B12: TC-ALC-002-01 | C12: F-ALC-02 + F-PRJ-A2 (Paid+NotStarted) match spec | D12: Supabase | E12: Not Run | F12: Not Run | G12: Fail | H12: Not Run | I12: Not Run | J12: Not Run | K12: Skipped
A13: D-10 | B13: TC-ALC-003-01 | C13: F-ALC-03 paid=0; status Pending | D13: Supabase | E13: Not Run | F13: Not Run | G13: Fail | H13: Not Run | I13: Not Run | J13: Not Run | K13: Skipped
A14: D-11 | B14: TC-ALC-004-01 | C14: F-ALC-04 paid=50% committed; status Partial | D14: Supabase | E14: Not Run | F14: Not Run | G14: Fail | H14: Not Run | I14: Not Run | J14: Not Run | K14: Skipped
A15: D-12 | B15: TC-ALC-005-01 | C15: F-INV-05 has 2 allocations; sums match | D15: Supabase | E15: Not Run | F15: Not Run | G15: Fail | H15: Not Run | I15: Not Run | J15: Not Run | K15: Skipped
... A21: D-18 | B21: TC-EXIT-001-01 | C21: F-PRJ-EXIT status Exit; payout fields populated | D21: Supabase | E21: Not Run | F21: Not Run | G21: Fail | H21: Not Run | I21: Not Run | J21: Not Run | K21: Skipped
A23: Pass / Total | E23: =IF(COUNTA(E4:E21)=0,"-",COUNTIF(E4:E21,"Pass")/18) | F23: =IF(COUNTA(F4:F21)=0,"-",COUNTIF(F4:F21,"Pass")/18) | G23: =IF(COUNTA(G4:G21)=0,"-",COUNTIF(G4:G21,"Pass")/18) | H23: =IF(COUNTA(H4:H21)=0,"-",COUNTIF(H4:H21,"Pass")/18) | I23: =IF(COUNTA(I4:I21)=0,"-",COUNTIF(I4:I21,"Pass")/18) | J23: =IF(COUNTA(J4:J21)=0,"-",COUNTIF(J4:J21,"Pass")/18) | K23: =IF(COUNTA(K4:K21)=0,"-",COUNTIF(K4:K21,"Pass")/18)

Sheet Defects
A1: Defect Log
A3: DEF ID | B3: Title | C3: Linked TC | D3: Linked Scenario | E3: Environment | F3: Layer | G3: Severity | H3: Priority | I3: Status | J3: Owner | K3: Filed on | L3: Closed on | M3: Root cause / Fix | N3: Re-test result
A4: DEF-2026-05-07-01 | B4: Schema drift: llps.last_synced_at column missing | C4: TC-SYNC-001-01 / D-01 | D4: SC-SYNC-001 | E4: Staging (anon REST) | F4: Supabase | G4: S2 | H4: P1 | I4: Open | J4: ARL Tech | K4: 2026-05-07
A5: DEF-2026-05-07-02 | B5: investor_units.allocation_status is NULL on all rows | C5: TC-ALC-001-01 .. TC-ALC-003-01 / D-08..D-12 | D5: SC-ALC-001..005 | E5: Staging (authenticated REST as Sahil Mohite) | F5: Supabase | G5: S2 | H5: P0 | I5: Open | J5: ARL Tech | K5: 2026-05-07
A6: DEF-2026-05-07-03 | B6: Zoho CRM -> Supabase sync not propagating: webhook never fires | C6: TC-LLP-001-04 / TC-SYNC-001-* (manual CRM->Supabase trace) | D6: SC-LLP-001 / SC-SYNC-001 | E6: Staging (authenticated REST + edge function probe) | F6: Sync | G6: S1 | H6: P0 | I6: Resolved (re-tested) | J6: ARL Tech | K6: 2026-05-07 | L6: 2026-05-15 | M6: zoho-crm-webhook v27 deployed + Zoho Custom Functions Push_Contact/LLP/Allocation_To_Supabase emit the v3 envelope. Wave 1 of 2026-05-15 ops-side E2E verified all 3 module updates land cleanly in webhook_log + downstream tables. | N6: PASS — see docs/e2e_test_results_ops_side_v27_2026-05-15.md Wave 1. Residual issue tracked as DEF-V27-01.
A7: DEF-2026-05-11-01 | B7: New LLPs default is_listed_in_marketplace=false → Explore tab never surfaces newly-synced LLPs | C7: TC-APP-001-06 | D7: SC-APP-001 | E7: Staging | F7: Supabase + Sync | G7: S2 | H7: P1 | I7: Resolved | J7: Claude (Opus 4.7) | K7: 2026-05-11 | L7: Webhook handleProject + reconcileLlps don't set is_listed_in_marketplace; defaults to false/null. Fix: derive from LLP_Status (true when Open for Reservation / Open for Issuance) OR add a CRM field and propagate. [RESOLVED 2026-05-11]: Backfilled 14 rows via UPDATE projects SET is_listed_in_marketplace=(status IN ('Open for Reservation','Open for Issuance')). Deployed isListedInMarketplace helper in both zoho-crm-webhook + zoho-reconcile-daily handlers. Verified UAT End-to-End LLP now appears in marketplace query (8 listed total). End-to-end fire test returned HTTP 200.
A8: DEF-2026-05-11-02 | B8: Supabase Auth rejects RFC 6761 .test TLD on inviteUserByEmail | C8: (N/A — runbook) | D8: SC-INV-001 | E8: Staging | F8: Auth | G8: S3 | H8: P3 | I8: Resolved | J8: Claude (Opus 4.7) | K8: 2026-05-11 | L8: auth.admin.inviteUserByEmail returned "Email ... is invalid" for an @arl.test address during Workstream 3 Step B. Use real domain (.com/.org) for any onboard tests. Document in onboard-investor README. [RESOLVED 2026-05-11]: Documented in onboard-investor index.ts header + docs/debug_runbook.md "Common errors" section. Behavioural change unnecessary — Supabase Auth validation is correct; doc warns against .test/.example/.invalid/.localhost TLDs.
A9: DEF-2026-05-11-03 | B9: Zoho createRecords API does NOT auto-fire workflow rules; webhook missed on programmatic creates | C9: (N/A — runbook) | D9: SC-SYNC-001 | E9: Staging | F9: Zoho | G9: S2 | H9: P2 | I9: Resolved | J9: Claude (Opus 4.7) | K9: 2026-05-11 | L9: createRecords without trigger:["workflow"] skips Supabase Sync workflow. Either set trigger in Deluge / API calls, or rely on zoho-reconcile-daily nightly catch-up. Reconcile already handles the gap but adds up-to-24h lag. [RESOLVED 2026-05-11]: Two-pronged. Programmatic creates should pass trigger:["workflow"] in body. docs/debug_runbook.md "Common errors" describes diagnosis + fix. docs/data_flow_guide.md item 11 codifies reconcile cron as catch-up path (worst-case 24h lag). No code-level callers in repo at fix time — fixture_payloads.json is reference-only.
A10: DEF-2026-05-11-04 | B10: LLP_UnitAllocation_Module.Name mandatory but Deluge Push_Allocation_To_Supabase does not enforce | C10: (N/A — runbook) | D10: SC-ALC-001 | E10: Staging | F10: Zoho/Deluge | G10: S3 | H10: P3 | I10: Resolved | J10: Claude (Opus 4.7) | K10: 2026-05-11 | L10: Step F createRecords failed MANDATORY_NOT_FOUND on Name field. UI creates auto-generate via auto-number; API creates must supply explicitly. Patch Deluge function to set Name from arl_id+investor or similar. [RESOLVED 2026-05-11]: Documented. docs/debug_runbook.md describes the MANDATORY_NOT_FOUND symptom; docs/data_flow_guide.md item 12 documents Name convention (UAT-<date>-<n> for fixtures, <arl_id>-<short_llp>-<seq> for production). Webhook handler ignores Name; it is purely Zoho display.
A11: DEF-2026-05-11-05 | B11: investors.zoho_contact_id is nullable + no UNIQUE constraint → duplicate-investor risk | C11: (N/A — schema) | D11: SC-INV-001 | E11: Staging | F11: Supabase schema | G11: S3 | H11: P3 | I11: Resolved | J11: Claude (Opus 4.7) | K11: 2026-05-11 | L11: onboard-investor accepts optional zoho_contact_id with no DB uniqueness guarantee. Two onboard calls with same zoho_contact_id but different emails would silently create two investors rows. Migration: ADD CONSTRAINT investors_zoho_contact_id_unique UNIQUE (zoho_contact_id) WHERE zoho_contact_id IS NOT NULL. [RESOLVED 2026-05-11]: Migration 20260511000000_025_investors_zoho_contact_id_unique.sql applied. Partial UNIQUE index investors_zoho_contact_id_unique blocks duplicate non-NULL zoho_contact_id; multiple NULLs still allowed for manual rows. Verified by attempted duplicate insert → 23505. Pre-existing investors_zoho_contact_id_key full UNIQUE coexists (redundant but harmless). Documented in data_flow_guide.md item 13 + debug_runbook.md "Common errors".
A12: DEF-2026-05-15-01 | B12: Marketplace: Sample Test LLP shows units_available=-30 — no DB CHECK guards Units_Issued > Total_Units from Zoho | C12: (N/A — audit) | D12: SC-APP-001 | E12: Live (oynfhdqizebvgmaoiuax) | F12: Supabase | G12: S2 | H12: P1 | I12: Resolved | J12: Claude (Opus 4.7) | K12: 46157 | L12: 46157 | M12: DEF-MKT-01 from docs/ops/marketplace.md §8. Hidden from Explore by is_listed_in_marketplace=false so no user impact, but indicates missing data validation. Recommend CHECK (units_issued >= 0 AND units_issued <= total_units) AND CHECK (units_available >= 0 AND units_available <= total_units), after cleaning the offending Sample Test LLP row. Engineering call required: tightening the constraint may reject legitimate Zoho payloads. [RESOLVED 2026-05-15] Migration 046 (ef769fa): cleaned Sample Test LLP row, added projects_units_nonneg CHECK constraint, made units_issued/units_available trigger-derived from investor_units. Webhook (38ad371) no longer writes those columns. | N12: Live verified post-046: Sample Test LLP units_available no longer negative; CHECK constraint rejects future violations.
A13: DEF-2026-05-15-02 | B13: Documents: storage_path drift — seed rows use 'documents/' prefix but storage RLS reads folder level 1 (common/project/investor) | C13: (N/A — audit) | D13: SC-DOC-001 | E13: Live (oynfhdqizebvgmaoiuax) | F13: Supabase + Storage RLS | G13: S2 | H13: P1 | I13: Resolved | J13: Claude (Opus 4.7) | K13: 46157 | L13: 46157 | M13: DOC-RLS-PATH from docs/ops/documents.md §8. Latent: arl-documents bucket is currently empty. Either (a) drop the 'documents/' prefix from the 4 seed rows in public.documents so paths match the RLS predicate, or (b) widen the RLS to look at folder level 2. Migration 033 header comment is misleading; the policy code is authoritative. Needs engineering decision. [RESOLVED 2026-05-15] Migration 047 (ef769fa): stripped 'documents/' prefix from the 4 seed rows, added documents_storage_path_no_bucket_prefix CHECK. Paths now match storage RLS folder-level-1 (common/, project/, investor/). | N13: Live verified post-047: the 4 seed rows no longer have the 'documents/' prefix; CHECK constraint blocks regression.
A14: DEF-2026-05-15-03 | B14: Tickets: status flips do not propagate to investor UI without manual refresh — no Realtime subscription on ticket providers | C14: (N/A — audit) | D14: SC-TKT-001 | E14: Live (oynfhdqizebvgmaoiuax) | F14: Flutter | G14: S3 | H14: P2 | I14: Resolved | J14: Claude (Opus 4.7) | K14: 46157 | L14: 46157 | M14: D-1 from docs/ops/tickets.md §10. _ticketsProvider + ticketByIdProvider are vanilla FutureProviders; GoRouter keepalive masks the staleness. Reproduced live in test 3 of investigation. Fix: introduce Supabase Realtime subscription on support_tickets + ticket_messages, OR auto-invalidate on screen focus. [RESOLVED 2026-05-15] Commit fb419c7: SupportScreen + TicketDetailScreen open a Supabase Realtime channel on support_tickets + ticket_messages and invalidate the providers on payload. | N14: Reproduce test 3 of investigation: flip ticket via Studio, observe support list updates without F5.
A15: DEF-2026-05-15-04 | B15: Tickets: new-ticket submit button overlaps bottom nav — first tap can land on /documents despite the POST having succeeded | C15: (N/A — audit) | D15: SC-TKT-001 | E15: Live (oynfhdqizebvgmaoiuax) | F15: Flutter UI | G15: S3 | H15: P2 | I15: Resolved | J15: Claude (Opus 4.7) | K15: 46157 | L15: 46157 | M15: D-2 from docs/ops/tickets.md §10. Visually appears as a silent failure. Fix: add bottom safe-area inset OR move CTA above the nav bar. [RESOLVED 2026-05-15] Commit fb419c7: new_ticket_screen.dart bottom padding now MediaQuery.viewPaddingOf(context).bottom + 24. | N15: Open new-ticket screen on 360x640 viewport; Submit button clears bottom nav.
A16: DEF-2026-05-15-05 | B16: Marketplace: 5 projects drift between projects.units_issued and SUM(investor_units.issued_units) — cards under-report | C16: (N/A — audit) | D16: SC-APP-001 | E16: Live (oynfhdqizebvgmaoiuax) | F16: Supabase + Sync | G16: S3 | H16: P2 | I16: Resolved | J16: Claude (Opus 4.7) | K16: 46157 | L16: 46157 | M16: DEF-MKT-02 from docs/ops/marketplace.md §8. Marketplace cards under-report issued units relative to live allocations. Recipe M-5 in the doc is the manual reconciliation workaround. Permanent fix blocked: a trigger that recomputes units_issued from investor_units would race the Zoho LLP webhook (which writes units_issued authoritatively on every LLP save). Plan: make units_available a GENERATED column AND remove edge-function writes to it. Engineering call required. [RESOLVED 2026-05-15] Migration 046 (ef769fa) + webhook (38ad371): units_issued derived via trg_recompute_project_units; units_available = GREATEST(total_units - units_issued, 0). Single writer. | N16: Post-046 backfill recomputed all 8 listed projects; SUM(investor_units.issued_units WHERE Issued) = projects.units_issued for every row.
A17: DEF-2026-05-15-06 | B17: Marketplace: projects.units_issued / units_available are NULLable with no default — 3 UAT rows had NULLs | C17: (N/A — audit) | D17: SC-APP-001 | E17: Live (oynfhdqizebvgmaoiuax) | F17: Supabase | G17: S3 | H17: P2 | I17: Resolved | J17: Claude (Opus 4.7) | K17: 46157 | L17: 46157 | M17: DEF-MKT-03 from docs/ops/marketplace.md §8. [RESOLVED 2026-05-15]: Migration 045 sets DEFAULT 0 on both columns and backfills the three NULL rows (Gamma Empty LLP-demo, UAT Test LLP 01, UAT Test LLP 02). Verified live: 0 NULLs remaining. | N17: Live verified post-045: SELECT COUNT(*) FROM projects WHERE units_issued IS NULL OR units_available IS NULL → 0.
A18: DEF-2026-05-15-07 | B18: Profile sync: webhook never pushes Zoho Contacts.Email to auth.users.email — sign-in email can drift from profile email | C18: (N/A — audit) | D18: SC-INV-001 | E18: Live (oynfhdqizebvgmaoiuax) | F18: Sync (zoho-crm-webhook) | G18: S3 | H18: P2 | I18: Resolved | J18: Claude (Opus 4.7) | K18: 46157 | L18: 46157 | M18: DEF-OPS-1 from docs/ops/investor_profile.md §14. zoho-crm-webhook updates public.investors.email but never calls auth.admin.update_user_by_id to sync auth.users.email. Investor edits email in Zoho → next day they can't sign in with the new address. Workaround: ops manually edits the auth user in Studio Dashboard → Auth → Users. Fix: extend webhook to also call admin.updateUserById when investors.email changes. [RESOLVED 2026-05-15] Commit 38ad371: handleContact calls supabase.auth.admin.updateUserById when the incoming email differs from cur.email. | N18: Change Contact.Email in Zoho → verify auth.users.email updates within 5s of webhook fire.
A19: DEF-2026-05-15-08 | B19: Notifications: exit-request approved → settled does NOT fire a notification — trigger gated on OLD.status='pending' | C19: (N/A — audit) | D19: SC-EXT-001 | E19: Live (oynfhdqizebvgmaoiuax) | F19: Supabase trigger | G19: S3 | H19: P2 | I19: Resolved | J19: Claude (Opus 4.7) | K19: 46157 | L19: 46157 | M19: DEF-OPS-2 from docs/ops/investor_profile.md §14. [RESOLVED 2026-05-15]: Migration 045 widens notify_exit_request_status_change() to fire on any transition INTO a terminal state (approved/rejected/settled) regardless of OLD.status. Body is keyed on NEW.status so path-independence is correct. The natural ops flow pending→approved→settled now fires both bells. | N19: Verified live by replaying the test investigation 4 scenario after migration 045 applied: approved → settled now produces a notification row.
A20: DEF-2026-05-15-09 | B20: Profile sync: webhook never pulls Zoho Contacts.Date_of_Birth or Contacts.Aadhaar_Number — only self-onboard path writes them | C20: (N/A — audit) | D20: SC-INV-001 | E20: Live (oynfhdqizebvgmaoiuax) | F20: Sync (zoho-crm-webhook) | G20: S3 | H20: P2 | I20: Resolved | J20: Claude (Opus 4.7) | K20: 46157 | L20: 46157 | M20: DEF-OPS-3 from docs/ops/investor_profile.md §14. Ops-side edits in Zoho to DOB or Aadhaar don't propagate to Supabase. Fix: add the two fields to the Contacts handler's UPSERT map. [RESOLVED 2026-05-15] Commit 38ad371: handleContact pulls Date_of_Birth (via asDate) + Aadhaar_Number into the investors UPSERT map. | N20: Change Contact.Date_of_Birth + Contacts.Aadhaar_Number in Zoho → verify investors row updates within 5s.
A21: DEF-2026-05-15-10 | B21: Sync: webhook does not handle LLP_UnitAllocation_Module delete — cancellations in Zoho leave Supabase rows active | C21: (N/A — audit) | D21: SC-ALC-001 | E21: Live (oynfhdqizebvgmaoiuax) | F21: Sync (zoho-crm-webhook) | G21: S3 | H21: P2 | I21: Resolved | J21: Claude (Opus 4.7) | K21: 46157 | L21: 46157 | M21: DEF-OPS-4 from docs/ops/investor_profile.md §14. Only Contacts and LLP_Creation_Module fan out the delete operation. Ops must manually UPDATE investor_units SET deleted_at=now() after cancelling in Zoho. Fix: add the operation=delete handler for allocations. [RESOLVED 2026-05-15] Commit 38ad371: handleAllocationDelete branch on operation=delete. Parent project recomputes via 046 trigger. | N21: Delete an LLP_UnitAllocation_Module record in Zoho → verify investor_units.deleted_at set + projects.units_issued recomputed.
A22: DEF-2026-05-15-11 | B22: KYC: kyc_resubmissions status changes do NOT fire a notification — investor learns only when ops separately flips investors.kyc_status | C22: (N/A — audit) | D22: SC-KYC-001 | E22: Live (oynfhdqizebvgmaoiuax) | F22: Supabase | G22: S3 | H22: P2 | I22: Resolved | J22: Claude (Opus 4.7) | K22: 46157 | L22: 46157 | M22: DEF-OPS-5 from docs/ops/investor_profile.md §14. Migration 034 added triggers on investors.kyc_status but not on kyc_resubmissions. Ops must remember to flip both. Fix: add an analogous trigger. [RESOLVED 2026-05-15] Migration 048 (4d8a34e) part A: trg_notify_kyc_resubmission_status_change emits 'kyc' notification on accepted|rejected. Table-existence-guarded. | N22: INSERT row in kyc_resubmissions (status=pending) → UPDATE status=accepted → verify notifications row inserted.
A23: DEF-2026-05-15-12 | B23: Tickets: My-Tickets list renders 36-char UUIDs instead of short forms — HTML design and mock use TKT-NNNN style | C23: (N/A — audit) | D23: SC-TKT-001 | E23: Live (oynfhdqizebvgmaoiuax) | F23: Flutter UI | G23: S3 | H23: P3 | I23: Resolved | J23: Claude (Opus 4.7) | K23: 46157 | L23: 46157 | M23: D-3 from docs/ops/tickets.md §10. Cosmetic. Easy fix in support_screen.dart formatter. [RESOLVED 2026-05-15] Commit fb419c7: support_screen.dart formats UUIDs to 8-char prefix; mocks pass through. | N23: Open /support → My-Tickets card renders '#<8-char prefix>' for real UUIDs; full UUID still in /ticket/<id> route.
... A29: DEF-2026-05-15-18 | B29: KYC: transitions into kyc_status='in_progress' do not fire a notification (only terminal states do) | C29: (N/A — audit) | D29: SC-KYC-001 | E29: Live (oynfhdqizebvgmaoiuax) | F29: Supabase trigger | G29: S3 | H29: P3 | I29: Resolved | J29: Claude (Opus 4.7) | K29: 46157 | L29: 46157 | M29: DEF-OPS-7 from docs/ops/investor_profile.md §14. Probably intentional, but not documented. Either add a notification or note as 'by design' in the trigger comment. [RESOLVED 2026-05-15] Migration 048 (4d8a34e) part C: COMMENT ON FUNCTION notify_investor_kyc_status_change documents the by-design choice that in_progress transitions do not fire a notification. | N29: SELECT obj_description('public.notify_investor_kyc_status_change'::regproc) → mentions BY DESIGN + DEF-2026-05-15-18.
A30: DEF-2026-05-15-E1 | B30: Notification card taps are no-op — should deep-link to ticket / KYC / exit detail | D30: SC-NOTIF | E30: Local web (port 5501) | F30: App | G30: S3 | H30: P2 | I30: Open | J30: ARL Tech | K30: 2026-05-15 | M30: Tapping notification cards on /activity does not navigate. Needs onTap handler wired to the right router route based on metadata.type.
A31: DEF-2026-05-15-E2 | B31: Financials sub-tab transition has overlap glitch (Payouts ↔ Financials) | D31: SC-APP | E31: Local web (port 5501) | F31: App | G31: S4 | H31: P3 | I31: Open | J31: ARL Tech | K31: 2026-05-15 | M31: Outgoing tab briefly overlaps incoming on tap. Pure cosmetic transition timing.
A32: DEF-2026-05-15-E3 | B32: /legal/privacy and /legal/terms redirect signed-in users to Home (compliance risk) | D32: SC-APP | E32: Local web (port 5501) | F32: Routing | G32: S2 | H32: P2 | I32: Open | J32: ARL Tech | K32: 2026-05-15 | M32: Both routes are in _publicRoutes in lib/core/navigation/router.dart:34-40. Redirect bounces signed-in users. Remove from _publicRoutes; route should be reachable in both auth states.
A33: DEF-2026-05-15-E4 | B33: KYC status mismatch — profile chip says "pending", Account row badge says "Verified" | D33: SC-KYC | E33: Local web (port 5501) | F33: App | G33: S3 | H33: P2 | I33: Open | J33: ARL Tech | K33: 2026-05-15 | M33: Top header reads investors.kyc_status; Account row badge appears hardcoded or reads a stale derived value. Reconcile both to a single source.
A34: DEF-2026-05-15-E5 | B34: Document eye-icon opens new tab with literal "null" in storage URL (seed path / RLS prefix mismatch) | D34: SC-DOC-001 | E34: Local web (port 5501) | F34: App + Storage | G34: S2 | H34: P2 | I34: Open | J34: ARL Tech | K34: 2026-05-15 | M34: Same root cause as docs/ops/documents.md §8 P1. Seed storage_path values have stray "documents/" prefix that doesn't match storage RLS predicate. Fix per ops doc Option A.
A35: DEF-2026-05-15-E6 | B35: Profile sub-screens render but URL stays on parent tab (deep-link / share-link breaks) | D35: SC-APP | E35: Local web (port 5501) | F35: Routing | G35: S4 | H35: P3 | I35: Open | J35: ARL Tech | K35: 2026-05-15 | M35: Profile sub-screens (KYC, Bank, Docs, Assistance) reached via push but URL not updated. Cosmetic / shareability issue.
A36: DEF-2026-05-15-E7 | B36: Gallery tile thumbnail tap is no-op — lightbox does not open | D36: SC-APP | E36: Local web (port 5501) | F36: App | G36: S4 | H36: P3 | I36: Open | J36: ARL Tech | K36: 2026-05-15 | M36: /gallery photo tile has no onTap handler wired to lightbox.
A37: DEF-V27-01 | B37: Contacts.update silently no-ops for non-existing investors — API-created Zoho contacts never land in public.investors | C37: (N/A — ops-side E2E v27) | D37: SC-INV-001 | E37: Live (oynfhdqizebvgmaoiuax) — zoho-crm-webhook v27 | F37: Sync (zoho-crm-webhook) | G37: S1 | H37: P1 | I37: Closed-Pass | J37: ARL Tech | K37: 2026-05-15 | L37: 2026-05-16 | M37: API-created Zoho Contacts fire Contacts.update (never .create). Handler matches by zoho_contact_id; finds nothing; marks status=processed without inserting. Fix: UPSERT on Contacts.update OR have the CF emit a .create event for first-seen records. | N37: v29 auto-onboard verified: TC-V29-WA-01. Brand-new Zoho Contact lands as investors+auth.users row within 15s; magic-link invite fires.
A38: DEF-V27-02 | B38: Allocation UTR/Date/Amount fields not unpacking into payouts table | C38: (N/A — ops-side E2E v27) | D38: SC-ALC-001 | E38: Live (oynfhdqizebvgmaoiuax) — zoho-crm-webhook v27 | F38: Sync (zoho-crm-webhook) | G38: S2 | H38: P2 | I38: Open | J38: ARL Tech | K38: 2026-05-15 | M38: Allocation 1169101000001654020 created with UTR_1/Date_1/Amount_1 populated. Webhook processed; no payouts row inserted. All existing payouts are source=manual. Either UTR-unpacking path was not wired in v27 or it requires an undocumented allocation_status / non-empty UTR_2. | N38: Partial fix in v29: slots 2-10 unpack correctly (TC-V29-WC-01, TC-V29-WC-02). Slot 1 still drops — split out as DEF-V29-04.
A39: DEF-V27-03 | B39: Zoho Bank_Name round-trips empty in webhook payload | C39: (N/A — ops-side E2E v27) | D39: SC-INV-001 | E39: Live (oynfhdqizebvgmaoiuax) — Zoho field config | F39: Zoho | G39: S4 | H39: P3 | I39: Open | J39: ARL Tech | K39: 2026-05-15 | M39: Wave 3 contact created with Bank_Name="HDFC Bank"; outbound webhook shows Bank_Name="". Likely a Zoho field-permission or picklist mapping issue. Not a Supabase bug. | N39: Triage on Zoho side.
A40: DEF-V27-04 | B40: aadhaar_masked stored as empty string when Zoho returns [REDACTED] sentinel | C40: (N/A — ops-side E2E v27) | D40: SC-INV-001 | E40: Live (oynfhdqizebvgmaoiuax) — zoho-crm-webhook v27 | F40: Sync + App display | G40: S4 | H40: P3 | I40: Open | J40: ARL Tech | K40: 2026-05-15 | M40: Aadhaar_Number arrives as the literal "[REDACTED]" sentinel from Zoho. Handler cannot compute a masked tail; writes empty string. App should render "not provided" rather than echo the empty value, or handler should accept a parallel non-redacted source field. | N40: P3 — cosmetic / data fidelity.
A41: DEF-V29-01 | B41: Zoho Allocation Delete trigger does not fire workflow webhook → Supabase mirror drift | C41: TC-V29-WP-03, TC-V29-WC-03 | D41: SC-V29 allocation | E41: Live (oynfhdqizebvgmaoiuax) — Zoho workflow rule | F41: Zoho workflow + Sync | G41: S1 | H41: P1 | I41: Open | J41: ARL Tech | K41: 2026-05-16 | M41: Deleting an LLP_UnitAllocation_Module record via the Zoho API (or UI) returns SUCCESS but no LLP_UnitAllocation_Module.delete event reaches the zoho-crm-webhook edge function (or webhook_log). Likely cause: the Zoho workflow rule for the Allocation module is not configured to fire on the Delete trigger, or Push_Allocation_To_Supabase is not subscribed to Delete. Reproduced twice in this session (Wave 1 throwaway alloc 1169101000001709007; Wave C alloc 1169101000001709020). Saved by parent-LLP CASCADE both times — but a standalone allocation delete will leave a phantom investor_units + payouts in Supabase. | N41: BLOCKING for any allocation lifecycle where the LLP outlives the allocation. Fix: wire Zoho workflow rule on Delete trigger for LLP_UnitAllocation_Module → Push_Allocation_To_Supabase with operation=delete.
A42: DEF-V29-02 | B42: Contacts.Phone (or Mobile) not mapped to investors.phone on auto-onboard / update | C42: TC-V29-WA-01 | D42: SC-V29 contacts | E42: Live (oynfhdqizebvgmaoiuax) — zoho-crm-webhook v29 | F42: Sync (zoho-crm-webhook) | G42: S2 | H42: P2 | I42: Open | J42: ARL Tech | K42: 2026-05-16 | M42: Zoho Contact created with Phone="+91 99999 00301" and Mobile=null. Resulting investors.phone is "" (empty). handleContact() in v29 source reads `phone: (d.Mobile ?? d.Phone)` — with d.Mobile=null that should fall through to d.Phone. Either Zoho CF strips Phone from the outbound payload, or the field arrives as empty string and `??` only catches null/undefined. Fix candidates: (a) coerce with `(d.Mobile || d.Phone || "")` to treat empty strings as nullish; (b) audit Zoho CF Push_Contact to confirm Phone is included. | N42: P2 — investor phone is a profile field that other parts of the app surface (support contact, KYC fallback).
A43: DEF-V29-03 | B43: LLP_Creation_Module webhook returns HTTP 400 "missing record id" for some LLPs (regression from v27) | C43: TC-V29-WB-01, TC-V29-WD-02 | D43: SC-V29 llp | E43: Live (oynfhdqizebvgmaoiuax) — Zoho Push_LLP CF + zoho-crm-webhook v29 | F43: Zoho CF + Sync | G43: S1 | H43: P1 | I43: Open | J43: ARL Tech | K43: 2026-05-16 | M43: In v27 logs LLP_Creation_Module.edit consistently returned 200. After v29 deploy 5 of 6 LLP webhook attempts in this session returned 400; the one that processed cleanly (Wave-D LLP 1169101000001677021) was created with a MINIMAL field set. The Wave-B LLP (1169101000001653013) — same Zoho user, same API — was created with address fields populated AND continued to 400 on every subsequent edit, even after retry with trigger=["workflow"]. The handler 400 happens in the pre-handler guard `if (!recordId) return 400` — so the inbound body has no `data.id` (or has `data: []` empty array). Strongly suggests Push_LLP CF (Deluge) is emitting a malformed payload for certain field combinations. Workaround in this session: SQL-injected llps+projects rows to simulate the missing webhook. | N43: BLOCKING for any new LLP onboarded via Zoho. Fix: triage Push_LLP Deluge script; confirm it always includes `id` in the body payload (or in the URL query string).
A44: DEF-V29-04 | B44: Allocation payout slot 1 silently dropped because Push_Allocation CF sends UTR_1="" instead of UTR=<value> | C44: TC-V29-WC-01 | D44: SC-V29 allocation | E44: Live (oynfhdqizebvgmaoiuax) — Push_Allocation CF + zoho-crm-webhook v29 | F44: Zoho CF + Sync | G44: S2 | H44: P2 | I44: Open | J44: ARL Tech | K44: 2026-05-16 | M44: Allocation created with Zoho-side fields UTR="UTRWC1-FIRST", Date_1="2026-05-16", Amount_1=50000 (slot 1 in Zoho uses bare `UTR` + `Date_1`/`Amount_1`). Outbound webhook payload (per webhook_log) carries UTR_1="" (empty string) and OMITS the UTR field. Handler slot-1 branch `(d.UTR_1 ?? d.UTR)` resolves to "" because `??` only short-circuits on null/undefined. The handler's guard `if (!utr || amt === undefined) continue` then skips slot 1. Slots 2–10 unpack fine. Fix candidates: (a) handler uses `||` instead of `??` for the UTR/Date fallback; (b) Push_Allocation CF includes the bare `UTR` field in the outbound payload alongside UTR_1. | N44: Partial close on DEF-V27-02. P2 — first payout of every CRM-sourced allocation is silently lost.
A54: DEF-V31-01 | B54: LR-SEC-005 regression: 4 of 5 edge functions still emit Access-Control-Allow-Origin: * (bank-change-request, create-ticket, reply-ticket, onboard-investor) | C54: V31-FIN-04 / V31-AUTH (cross-fn) | D54: — | E54: Production | F54: Edge Function | G54: S2 | H54: P1 | I54: Open | J54: ARL Tech | K54: 2026-05-18 | M54: Code in supabase/functions/*/index.ts still hardcodes ACAO=*; _shared/cors.ts allow-list is in repo but deployed function versions (v11) predate the 2026-05-13 audit. Re-deploy with `supabase functions deploy <name>` for all 4. JWT remains the real gate; severity is S2 because impact is mostly defense-in-depth.
